Workbook

Sheet 1) Kpler
A1: . | E1: Name | F1: Capacity (m3) | G1: Deadweight | H1: State | I1: Status | J1: MMSI | K1: IMO | L1: Next destination | M1: Next destination ETA | N1: Loaded | Q1: LAST DOWNLOADED | U1: According to Kpler: | Y1: From '2) VLGC' + "India, Iran, FS" | AA1: Not In Kpler List | AE1: VLEC Check > 93k cbm | AF1: Not in Kpler. In Sorter | AG1: In Kpler. Not in sorter
A2: From 2) Tracker | B2: =COUNTA('2) Tracker'!A3:A510) -> 341 | E2: Al Ain | F2: 86000 | G2: 55324 | H2: loaded | I2: Active | J2: 636021495 | K2: 9916812 | N2: TRUE | U2: Actively trading: | V2: =COUNTIF($I$2:$I$1000,"active") -> 473 | Y2: =IFERROR(__xludf.DUMMYFUNCTION("filter($E$4:$E$600,not(countif('2) Tracker'!$A$3:$A$609,$E$4:$E$600)))"),"Apollo Ocean") -> Apollo Ocean | Z2: 1 | AA2: =IFERROR(__xludf.DUMMYFUNCTION("FILTER(Y2:Y501, ISNA(MATCH(TRIM(LOWER(CLEAN(Y2:Y501))), $E$2:$E$501, 0)))"),"") | AC2: NEWSHIPS? | AE2: =IF(E174="","", IF(F2>93000,1,"")) | AF2: =IF(ISERROR(VLOOKUP(#REF!,$E$2:$F$600,2, FALSE)),1,"") -> 1 | AG2: =IF(ISERROR(VLOOKUP(E174,$Y$2:$Z$600,2,FALSE)),1,"") -> 1
A3: From 3) Sorter | B3: =COUNTA('3) Sorter'!F4:F507) -> 349 | E3: Al Maryah | F3: 83765 | G3: 54474 | H3: ballast | I3: Active | J3: 636023795 | K3: 9393682 | N3: FALSE | Q3: Date | R3: Time | S3: By: | U3: Soon-to-be delivered | V3: =COUNTIF($I$2:$I$1000,"under construction") -> 25 | Y3: =IFERROR(__xludf.DUMMYFUNCTION("""COMPUTED_VALUE"""),"Astra") -> Astra | AC3: =IFERROR(__xludf.DUMMYFUNCTION("FILTER(E2:E501, ISNA(MATCH(TRIM(LOWER(CLEAN(E2:E501))), $Y$2:$Y$501, 0)))"),"Al Ain") -> Al Ain | AE3: =IF(E3="","", IF(F3>93000,1,"")) | AF3: =IF(ISERROR(VLOOKUP(Y3,$E$2:$F$600,2, FALSE)),1,"") | AG3: =IF(ISERROR(VLOOKUP(E3,$Y$2:$Z$600,2,FALSE)),1,"") -> 1
A4: Missing: | B4: =B2-B3 -> -8 | E4: Al Salam | F4: 86000 | G4: 54000 | H4: loaded | I4: Active | J4: 636021498 | K4: 9923085 | N4: TRUE | Q4: 46125 | R4: 0.41666667 | S4: GP | U4: VLEC | V4: =SUM(AE2:AE500) -> #REF! | Y4: =IFERROR(__xludf.DUMMYFUNCTION("""COMPUTED_VALUE"""),"Astram") -> Astram | AC4: =IFERROR(__xludf.DUMMYFUNCTION("""COMPUTED_VALUE"""),"Al Maryah") -> Al Maryah | AE4: =IF(E4="","", IF(F4>93000,1,"")) | AF4: =IF(ISERROR(VLOOKUP(Y4,$E$2:$F$600,2, FALSE)),1,"") | AG4: =IF(ISERROR(VLOOKUP(E4,$Y$2:$Z$600,2,FALSE)),1,"") -> 1
A5: In 2) but not in 3) | B5: In 3) but not in 2) | E5: Al Wukir | F5: 80841 | G5: 53999 | H5: ballast | I5: Active | J5: 538005255 | K5: 9359466 | L5: Houston | M5: 46138.125 | N5: FALSE | U5: Not in Kpler. In Sorter | V5: =SUM(AF2:AF399) -> 275 | Y5: =IFERROR(__xludf.DUMMYFUNCTION("""COMPUTED_VALUE"""),"Aura") -> Aura | AC5: =IFERROR(__xludf.DUMMYFUNCTION("""COMPUTED_VALUE"""),"Al Salam") -> Al Salam | AE5: =IF(E5="","", IF(F5>93000,1,"")) | AF5: =IF(ISERROR(VLOOKUP(Y5,$E$2:$F$600,2, FALSE)),1,"") | AG5: =IF(ISERROR(VLOOKUP(E5,$Y$2:$Z$600,2,FALSE)),1,"") -> 1
A6: =IFERROR(__xludf.DUMMYFUNCTION("filter('2) Tracker'!$A3:$A$402,not(countif('3) Sorter'!$F$4:$F$344,'2) Tracker'!$A$3:$A$402)))"),"") | B6: =IFERROR(__xludf.DUMMYFUNCTION("filter('3) Sorter'!$F$4:$F$366,not(countif('2) Tracker'!$A$3:$A$503,'3) Sorter'!$F$4:$F$366)))"),"") | E6: Albert | F6: 84000 | G6: 54354 | H6: loaded | I6: Active | J6: 371353000 | K6: 9682447 | L6: Pajaritos | M6: 46132.625 | N6: TRUE | U6: In Kpler. Not in sorter | V6: =SUM(AG2:AG394) -> 303 | Y6: =IFERROR(__xludf.DUMMYFUNCTION("""COMPUTED_VALUE"""),"Aurora") -> Aurora | AC6: =IFERROR(__xludf.DUMMYFUNCTION("""COMPUTED_VALUE"""),"Al Wukir") -> Al Wukir | AE6: =IF(E6="","", IF(F6>93000,1,"")) | AF6: =IF(ISERROR(VLOOKUP(Y6,$E$2:$F$600,2, FALSE)),1,"") | AG6: =IF(ISERROR(VLOOKUP(E6,$Y$2:$Z$600,2,FALSE)),1,"") -> 1
E7: Albert Ii | F7: 84000 | G7: 54358 | H7: loaded | I7: Active | J7: 371669000 | K7: 9780732 | L7: Houston | M7: 46134.896 | N7: TRUE | Y7: =IFERROR(__xludf.DUMMYFUNCTION("""COMPUTED_VALUE"""),"Axon I") -> Axon I | AC7: =IFERROR(__xludf.DUMMYFUNCTION("""COMPUTED_VALUE"""),"Albert") -> Albert | AE7: =IF(E7="","", IF(F7>93000,1,"")) | AF7: =IF(ISERROR(VLOOKUP(Y7,$E$2:$F$600,2, FALSE)),1,"") | AG7: =IF(ISERROR(VLOOKUP(E7,$Y$2:$Z$600,2,FALSE)),1,"") -> 1
E8: Albert Iii | F8: 84000 | G8: 54365 | H8: ballast | I8: Active | J8: 371557000 | K8: 9794288 | L8: Energy Transfer Nederland | M8: 46132.542 | N8: FALSE | U8: Newbuilds | Y8: =IFERROR(__xludf.DUMMYFUNCTION("""COMPUTED_VALUE"""),"Banian") -> Banian | AC8: =IFERROR(__xludf.DUMMYFUNCTION("""COMPUTED_VALUE"""),"Albert Ii") -> Albert Ii | AE8: =IF(E8="","", IF(F8>93000,1,"")) | AF8: =IF(ISERROR(VLOOKUP(Y8,$E$2:$F$600,2, FALSE)),1,"") | AG8: =IF(ISERROR(VLOOKUP(E8,$Y$2:$Z$600,2,FALSE)),1,"") -> 1
E9: Apollo Ocean | F9: 78907 | G9: 49999 | H9: ballast | I9: Active | J9: 574005600 | K9: 9423322 | L9: Advario Oman | M9: 46134.458 | N9: FALSE | U9: 1) Manual check on all the under constructions with newbuild list | Y9: =IFERROR(__xludf.DUMMYFUNCTION("""COMPUTED_VALUE"""),"Bao Yu") -> Bao Yu | AC9: =IFERROR(__xludf.DUMMYFUNCTION("""COMPUTED_VALUE"""),"Albert Iii") -> Albert Iii | AE9: =IF(E9="","", IF(F9>93000,1,"")) | AF9: =IF(ISERROR(VLOOKUP(Y9,$E$2:$F$600,2, FALSE)),1,"") | AG9: =IF(ISERROR(VLOOKUP(E9,$Y$2:$Z$600,2,FALSE)),1,"")
E10: Aquamarine Progress | F10: 83278 | G10: 54866 | H10: ballast | I10: Active | J10: 565210000 | K10: 9415650 | L10: Houston | M10: 46159.208 | N10: FALSE | Y10: =IFERROR(__xludf.DUMMYFUNCTION("""COMPUTED_VALUE"""),"Bw Birch") -> Bw Birch | AC10: =IFERROR(__xludf.DUMMYFUNCTION("""COMPUTED_VALUE"""),"Aquamarine Progress") -> Aquamarine Progress | AE10: =IF(E10="","", IF(F10>93000,1,"")) | AF10: =IF(ISERROR(VLOOKUP(Y10,$E$2:$F$600,2, FALSE)),1,"") | AG10: =IF(ISERROR(VLOOKUP(E10,$Y$2:$Z$600,2,FALSE)),1,"") -> 1
E11: Aquamarine Progress Ii | F11: 87000 | G11: 56805 | H11: ballast | I11: Active | J11: 563220700 | K11: 9947495 | L11: Houston | M11: 46137.292 | N11: FALSE | Y11: =IFERROR(__xludf.DUMMYFUNCTION("""COMPUTED_VALUE"""),"Bw Chinook") -> Bw Chinook | AC11: =IFERROR(__xludf.DUMMYFUNCTION("""COMPUTED_VALUE"""),"Aquamarine Progress Ii") -> Aquamarine Progress Ii | AE11: =IF(E11="","", IF(F11>93000,1,"")) | AF11: =IF(ISERROR(VLOOKUP(Y11,$E$2:$F$600,2, FALSE)),1,"") | AG11: =IF(ISERROR(VLOOKUP(E11,$Y$2:$Z$600,2,FALSE)),1,"") -> 1
E12: Astir Thuban | F12: 80546 | G12: 54650 | H12: ballast | I12: Active | J12: 636018567 | K12: 9840867 | L12: Energy Transfer Nederland | M12: 46134.042 | N12: FALSE | Y12: =IFERROR(__xludf.DUMMYFUNCTION("""COMPUTED_VALUE"""),"Bw Oak") -> Bw Oak | AC12: =IFERROR(__xludf.DUMMYFUNCTION("""COMPUTED_VALUE"""),"Astir Thuban") -> Astir Thuban | AE12: =IF(E12="","", IF(F12>93000,1,"")) | AF12: =IF(ISERROR(VLOOKUP(Y12,$E$2:$F$600,2, FALSE)),1,"") | AG12: =IF(ISERROR(VLOOKUP(E12,$Y$2:$Z$600,2,FALSE)),1,"") -> 1
E13: Astomos Earth | F13: 83426 | G13: 55250 | H13: ballast | I13: Active | J13: 373740000 | K13: 9607069 | L13: Freeport Texas | M13: 46154.646 | N13: FALSE | U13: Daily | Y13: =IFERROR(__xludf.DUMMYFUNCTION("""COMPUTED_VALUE"""),"Bw Tyr") -> Bw Tyr | AC13: =IFERROR(__xludf.DUMMYFUNCTION("""COMPUTED_VALUE"""),"Astomos Earth") -> Astomos Earth | AE13: =IF(E13="","", IF(F13>93000,1,"")) | AF13: =IF(ISERROR(VLOOKUP(Y13,$E$2:$F$600,2, FALSE)),1,"") | AG13: =IF(ISERROR(VLOOKUP(E13,$Y$2:$Z$600,2,FALSE)),1,"") -> 1
E14: Astomos Venus | F14: 83000 | G14: 55209 | H14: loaded | I14: Active | J14: 374614000 | K14: 9738545 | N14: TRUE | U14: WA -> Position lists | Y14: =IFERROR(__xludf.DUMMYFUNCTION("""COMPUTED_VALUE"""),"Celeste") -> Celeste | AC14: =IFERROR(__xludf.DUMMYFUNCTION("""COMPUTED_VALUE"""),"Astomos Venus") -> Astomos Venus | AE14: =IF(E14="","", IF(F14>93000,1,"")) | AF14: =IF(ISERROR(VLOOKUP(Y14,$E$2:$F$600,2, FALSE)),1,"") | AG14: =IF(ISERROR(VLOOKUP(E14,$Y$2:$Z$600,2,FALSE)),1,"") -> 1
E15: Astra | F15: 82000 | G15: 54368 | H15: ballast | I15: Active | J15: 650000174 | K15: 9350422 | L15: Advario Oman | M15: 46133.75 | N15: FALSE | U15: 1) Sorter to align with position lists | Y15: =IFERROR(__xludf.DUMMYFUNCTION("""COMPUTED_VALUE"""),"Clipper Galiot") -> Clipper Galiot | AC15: =IFERROR(__xludf.DUMMYFUNCTION("""COMPUTED_VALUE"""),"Atlantic Victory") -> Atlantic Victory | AE15: =IF(E15="","", IF(F15>93000,1,"")) | AF15: =IF(ISERROR(VLOOKUP(Y15,$E$2:$F$600,2, FALSE)),1,"") | AG15: =IF(ISERROR(VLOOKUP(E15,$Y$2:$Z$600,2,FALSE)),1,"")
E16: Astram | F16: 81605 | G16: 54533 | H16: ballast | I16: Active | J16: 603914000 | K16: 9307748 | L16: Khor Fakkan Anchorage | M16: 46132.875 | N16: FALSE | U16: 2) VL and Product operations info to be reflected | Y16: =IFERROR(__xludf.DUMMYFUNCTION("""COMPUTED_VALUE"""),"Clipper Galleon") -> Clipper Galleon | AC16: =IFERROR(__xludf.DUMMYFUNCTION("""COMPUTED_VALUE"""),"Atlantic Voyager") -> Atlantic Voyager | AE16: =IF(E16="","", IF(F16>93000,1,"")) | AF16: =IF(ISERROR(VLOOKUP(Y16,$E$2:$F$600,2, FALSE)),1,"") | AG16: =IF(ISERROR(VLOOKUP(E16,$Y$2:$Z$600,2,FALSE)),1,"")
E17: Atlantic Victory | F17: 75000 | G17: 54048 | H17: loaded | I17: Active | J17: 352003378 | K17: 9379399 | N17: TRUE | U17: 3) Haldia / India line up to be updated | Y17: =IFERROR(__xludf.DUMMYFUNCTION("""COMPUTED_VALUE"""),"Clipper Gannet") -> Clipper Gannet | AC17: =IFERROR(__xludf.DUMMYFUNCTION("""COMPUTED_VALUE"""),"Aurora Guardian") -> Aurora Guardian | AE17: =IF(E17="","", IF(F17>93000,1,"")) | AF17: =IF(ISERROR(VLOOKUP(Y17,$E$2:$F$600,2, FALSE)),1,"") | AG17: =IF(ISERROR(VLOOKUP(E17,$Y$2:$Z$600,2,FALSE)),1,"") -> 1
E18: Atlantic Voyager | F18: 87000 | G18: 55885 | H18: ballast | I18: Active | J18: 311001673 | K18: 9996020 | L18: Ningbo Area | M18: 46145.625 | N18: FALSE | Y18: =IFERROR(__xludf.DUMMYFUNCTION("""COMPUTED_VALUE"""),"Clipper Genesis") -> Clipper Genesis | AC18: =IFERROR(__xludf.DUMMYFUNCTION("""COMPUTED_VALUE"""),"Axis River") -> Axis River | AE18: =IF(E18="","", IF(F18>93000,1,"")) | AF18: =IF(ISERROR(VLOOKUP(Y2,$E$2:$F$600,2, FALSE)),1,"") | AG18: =IF(ISERROR(VLOOKUP(E18,$Y$2:$Z$600,2,FALSE)),1,"") -> 1
E19: Aura | F19: 80138 | G19: 53395 | H19: floatingStorage | I19: Active | J19: 650000181 | K19: 9274563 | L19: Guangzhou | M19: 46133.125 | N19: TRUE | U19: Then use Kpler AIS to update | Y19: =IFERROR(__xludf.DUMMYFUNCTION("""COMPUTED_VALUE"""),"Clipper Geneva") -> Clipper Geneva | AC19: =IFERROR(__xludf.DUMMYFUNCTION("""COMPUTED_VALUE"""),"Ayame") -> Ayame | AE19: =IF(E19="","", IF(F19>93000,1,"")) | AF19: =IF(ISERROR(VLOOKUP(Y19,$E$2:$F$600,2, FALSE)),1,"") | AG19: =IF(ISERROR(VLOOKUP(E19,$Y$2:$Z$600,2,FALSE)),1,"")
E20: Aurora | F20: 78462 | G20: 49679 | H20: loaded | I20: Active | J20: 511101458 | K20: 9088536 | N20: TRUE | Y20: =IFERROR(__xludf.DUMMYFUNCTION("""COMPUTED_VALUE"""),"Clipper Grace") -> Clipper Grace | AC20: =IFERROR(__xludf.DUMMYFUNCTION("""COMPUTED_VALUE"""),"Badrinath") -> Badrinath | AE20: =IF(E20="","", IF(F20>93000,1,"")) | AF20: =IF(ISERROR(VLOOKUP(Y20,$E$2:$F$600,2, FALSE)),1,"") | AG20: =IF(ISERROR(VLOOKUP(E20,$Y$2:$Z$600,2,FALSE)),1,"")
E21: Aurora Guardian | F21: 86700 | G21: 55000 | H21: underConstruction | I21: Under Construction | J21: 563319300 | K21: 1015399 | N21: FALSE | Y21: =IFERROR(__xludf.DUMMYFUNCTION("""COMPUTED_VALUE"""),"Clipper Guardian") -> Clipper Guardian | AC21: =IFERROR(__xludf.DUMMYFUNCTION("""COMPUTED_VALUE"""),"Baynounah") -> Baynounah | AE21: =IF(E21="","", IF(F21>93000,1,"")) | AF21: =IF(ISERROR(VLOOKUP(Y21,$E$2:$F$600,2, FALSE)),1,"") | AG21: =IF(ISERROR(VLOOKUP(E21,$Y$2:$Z$600,2,FALSE)),1,"") -> 1
E22: Axis River | F22: 86700 | G22: 55000 | H22: ballast | I22: Active | J22: 352002455 | K22: 9949704 | L22: RIPET | M22: 46133.833 | N22: FALSE | Y22: =IFERROR(__xludf.DUMMYFUNCTION("""COMPUTED_VALUE"""),"Da Li") -> Da Li | AC22: =IFERROR(__xludf.DUMMYFUNCTION("""COMPUTED_VALUE"""),"Bella Niagara") -> Bella Niagara | AE22: =IF(E22="","", IF(F22>93000,1,"")) | AF22: =IF(ISERROR(VLOOKUP(Y22,$E$2:$F$600,2, FALSE)),1,"") | AG22: =IF(ISERROR(VLOOKUP(E22,$Y$2:$Z$600,2,FALSE)),1,"") -> 1
E23: Axon I | F23: 76905 | G23: 49874 | H23: ballast | I23: Active | J23: 603920000 | K23: 9005053 | L23: Sharjah | M23: 46132.583 | N23: FALSE | Y23: =IFERROR(__xludf.DUMMYFUNCTION("""COMPUTED_VALUE"""),"Danisa") -> Danisa | AC23: =IFERROR(__xludf.DUMMYFUNCTION("""COMPUTED_VALUE"""),"Bellavista Explorer") -> Bellavista Explorer | AE23: =IF(E23="","", IF(F23>93000,1,"")) | AF23: =IF(ISERROR(VLOOKUP(Y23,$E$2:$F$600,2, FALSE)),1,"") | AG23: =IF(ISERROR(VLOOKUP(E23,$Y$2:$Z$600,2,FALSE)),1,"")
E24: Ayame | F24: 81605 | G24: 55076 | H24: ballast | I24: Active | J24: 565238000 | K24: 9415662 | N24: FALSE | Y24: =IFERROR(__xludf.DUMMYFUNCTION("""COMPUTED_VALUE"""),"Danuta I") -> Danuta I | AC24: =IFERROR(__xludf.DUMMYFUNCTION("""COMPUTED_VALUE"""),"Berge Nantong") -> Berge Nantong | AE24: =IF(E24="","", IF(F24>93000,1,"")) | AF24: =IF(ISERROR(VLOOKUP(Y24,$E$2:$F$600,2, FALSE)),1,"") | AG24: =IF(ISERROR(VLOOKUP(E24,$Y$2:$Z$600,2,FALSE)),1,"") -> 1
E25: Badrinath | F25: 82230 | G25: 54901 | H25: loaded | I25: Active | J25: 538011595 | K25: 9608300 | L25: Mangalore | M25: 46169.5 | N25: TRUE | Y25: =IFERROR(__xludf.DUMMYFUNCTION("""COMPUTED_VALUE"""),"Double In") -> Double In | AC25: =IFERROR(__xludf.DUMMYFUNCTION("""COMPUTED_VALUE"""),"Berge Ningbo") -> Berge Ningbo | AE25: =IF(E25="","", IF(F25>93000,1,"")) | AF25: =IF(ISERROR(VLOOKUP(Y25,$E$2:$F$600,2, FALSE)),1,"") | AG25: =IF(ISERROR(VLOOKUP(E25,$Y$2:$Z$600,2,FALSE)),1,"") -> 1
E26: Banian | F26: 76928 | G26: 49999 | H26: loaded | I26: Active | J26: 603919000 | K26: 9046784 | N26: TRUE | Y26: =IFERROR(__xludf.DUMMYFUNCTION("""COMPUTED_VALUE"""),"Elly") -> Elly | AC26: =IFERROR(__xludf.DUMMYFUNCTION("""COMPUTED_VALUE"""),"Bonneville") -> Bonneville | AE26: =IF(E26="","", IF(F26>93000,1,"")) | AF26: =IF(ISERROR(VLOOKUP(Y26,$E$2:$F$600,2, FALSE)),1,"") | AG26: =IF(ISERROR(VLOOKUP(E26,$Y$2:$Z$600,2,FALSE)),1,"")
E27: Bao Yu | F27: 76194 | G27: 51466 | H27: ballast | I27: Active | J27: 610000074 | K27: 8519966 | N27: FALSE | Y27: =IFERROR(__xludf.DUMMYFUNCTION("""COMPUTED_VALUE"""),"Energia Soleil") -> Energia Soleil | AC27: =IFERROR(__xludf.DUMMYFUNCTION("""COMPUTED_VALUE"""),"Boreal Pioneer") -> Boreal Pioneer | AE27: =IF(E27="","", IF(F27>93000,1,"")) | AF27: =IF(ISERROR(VLOOKUP(Y27,$E$2:$F$600,2, FALSE)),1,"") | AG27: =IF(ISERROR(VLOOKUP(E27,$Y$2:$Z$600,2,FALSE)),1,"")
E28: Baynounah | F28: 86000 | G28: 54000 | H28: ballast | I28: Active | J28: 636021499 | K28: 9923097 | N28: FALSE | Y28: =IFERROR(__xludf.DUMMYFUNCTION("""COMPUTED_VALUE"""),"Exonave") -> Exonave | AC28: =IFERROR(__xludf.DUMMYFUNCTION("""COMPUTED_VALUE"""),"Boreal Voyager") -> Boreal Voyager | AE28: =IF(E28="","", IF(F28>93000,1,"")) | AF28: =IF(ISERROR(VLOOKUP(Y28,$E$2:$F$600,2, FALSE)),1,"") | AG28: =IF(ISERROR(VLOOKUP(E28,$Y$2:$Z$600,2,FALSE)),1,"") -> 1
E29: Bella Niagara | F29: 91000 | G29: 62500 | H29: ballast | I29: Active | J29: 636022369 | K29: 9933781 | L29: Energy Transfer Nederland | M29: 46143.667 | N29: FALSE | Y29: =IFERROR(__xludf.DUMMYFUNCTION("""COMPUTED_VALUE"""),"Fas Gas") -> Fas Gas | AC29: =IFERROR(__xludf.DUMMYFUNCTION("""COMPUTED_VALUE"""),"Botan") -> Botan | AE29: =IF(E29="","", IF(F29>93000,1,"")) | AF29: =IF(ISERROR(VLOOKUP(Y29,$E$2:$F$600,2, FALSE)),1,"") | AG29: =IF(ISERROR(VLOOKUP(E29,$Y$2:$Z$600,2,FALSE)),1,"") -> 1
E30: Bellavista Explorer | F30: 90000 | G30: 54000 | H30: loaded | I30: Active | J30: 538090722 | K30: 9895305 | L30: FREP Plant | M30: 46141.5 | N30: TRUE | Y30: =IFERROR(__xludf.DUMMYFUNCTION("""COMPUTED_VALUE"""),"Fogas") -> Fogas | AC30: =IFERROR(__xludf.DUMMYFUNCTION("""COMPUTED_VALUE"""),"Brizo") -> Brizo | AE30: =IF(E30="","", IF(F30>93000,1,"")) | AF30: =IF(ISERROR(VLOOKUP(Y30,$E$2:$F$600,2, FALSE)),1,"") | AG30: =IF(ISERROR(VLOOKUP(E30,$Y$2:$Z$600,2,FALSE)),1,"") -> 1
E31: Berge Nantong | F31: 80360 | G31: 58757 | H31: ballast | I31: Active | J31: 477241500 | K31: 9317987 | L31: Houston | M31: 46144.5 | N31: FALSE | Y31: =IFERROR(__xludf.DUMMYFUNCTION("""COMPUTED_VALUE"""),"Fotis") -> Fotis | AC31: =IFERROR(__xludf.DUMMYFUNCTION("""COMPUTED_VALUE"""),"Bw Aries") -> Bw Aries | AE31: =IF(E31="","", IF(F31>93000,1,"")) | AF31: =IF(ISERROR(VLOOKUP(Y31,$E$2:$F$600,2, FALSE)),1,"") | AG31: =IF(ISERROR(VLOOKUP(E31,$Y$2:$Z$600,2,FALSE)),1,"") -> 1
E32: Berge Ningbo | F32: 80607 | G32: 58899 | H32: ballast | I32: Active | J32: 477099600 | K32: 9308493 | L32: Port Elizabeth | M32: 46135.833 | N32: FALSE | Y32: =IFERROR(__xludf.DUMMYFUNCTION("""COMPUTED_VALUE"""),"Future Japan") -> Future Japan | AC32: =IFERROR(__xludf.DUMMYFUNCTION("""COMPUTED_VALUE"""),"Bw Avior") -> Bw Avior | AE32: =IF(E32="","", IF(F32>93000,1,"")) | AF32: =IF(ISERROR(VLOOKUP(Y32,$E$2:$F$600,2, FALSE)),1,"") | AG32: =IF(ISERROR(VLOOKUP(E32,$Y$2:$Z$600,2,FALSE)),1,"") -> 1
E33: Bonneville | F33: 88000 | G33: 56044 | H33: ballast | I33: Active | J33: 636022845 | K33: 9993626 | L33: Houston | M33: 46135.75 | N33: FALSE | Y33: =IFERROR(__xludf.DUMMYFUNCTION("""COMPUTED_VALUE"""),"Gafus") -> Gafus | AC33: =IFERROR(__xludf.DUMMYFUNCTION("""COMPUTED_VALUE"""),"Bw Balder") -> Bw Balder | AE33: =IF(E33="","", IF(F33>93000,1,"")) | AF33: =IF(ISERROR(VLOOKUP(Y33,$E$2:$F$600,2, FALSE)),1,"") | AG33: =IF(ISERROR(VLOOKUP(E33,$Y$2:$Z$600,2,FALSE)),1,"") -> 1
E34: Boreal Pioneer | F34: 91000 | G34: 59206 | H34: ballast | I34: Active | J34: 636023404 | K34: 9945198 | L34: RIPET | M34: 46135.125 | N34: FALSE | Y34: =IFERROR(__xludf.DUMMYFUNCTION("""COMPUTED_VALUE"""),"Galvin") -> Galvin | AC34: =IFERROR(__xludf.DUMMYFUNCTION("""COMPUTED_VALUE"""),"Bw Brage") -> Bw Brage | AE34: =IF(E34="","", IF(F34>93000,1,"")) | AF34: =IF(ISERROR(VLOOKUP(Y34,$E$2:$F$600,2, FALSE)),1,"") | AG34: =IF(ISERROR(VLOOKUP(E34,$Y$2:$Z$600,2,FALSE)),1,"") -> 1
E35: Boreal Voyager | F35: 91000 | G35: 58263 | H35: loaded | I35: Active | J35: 636023667 | K35: 9945203 | L35: Wenzhou | M35: 46132.708 | N35: TRUE | Y35: =IFERROR(__xludf.DUMMYFUNCTION("""COMPUTED_VALUE"""),"Gardian") -> Gardian | AC35: =IFERROR(__xludf.DUMMYFUNCTION("""COMPUTED_VALUE"""),"Bw Breeze") -> Bw Breeze | AE35: =IF(E35="","", IF(F35>93000,1,"")) | AF35: =IF(ISERROR(VLOOKUP(Y35,$E$2:$F$600,2, FALSE)),1,"") | AG35: =IF(ISERROR(VLOOKUP(E35,$Y$2:$Z$600,2,FALSE)),1,"") -> 1
E36: Botan | F36: 91000 | G36: 59312 | H36: ballast | I36: Active | J36: 538010117 | K36: 9940966 | L36: Singapore | M36: 46133.667 | N36: FALSE | Y36: =IFERROR(__xludf.DUMMYFUNCTION("""COMPUTED_VALUE"""),"Gas Concept") -> Gas Concept | AC36: =IFERROR(__xludf.DUMMYFUNCTION("""COMPUTED_VALUE"""),"Bw Capella") -> Bw Capella | AE36: =IF(E36="","", IF(F36>93000,1,"")) | AF36: =IF(ISERROR(VLOOKUP(Y36,$E$2:$F$600,2, FALSE)),1,"") | AG36: =IF(ISERROR(VLOOKUP(E36,$Y$2:$Z$600,2,FALSE)),1,"") -> 1
E37: Brizo | F37: 82557 | G37: 53677 | H37: ballast | I37: Active | J37: 352004952 | K37: 9238284 | N37: FALSE | Y37: =IFERROR(__xludf.DUMMYFUNCTION("""COMPUTED_VALUE"""),"Gas Endurance") -> Gas Endurance | AC37: =IFERROR(__xludf.DUMMYFUNCTION("""COMPUTED_VALUE"""),"Bw Carina") -> Bw Carina | AE37: =IF(E37="","", IF(F37>93000,1,"")) | AF37: =IF(ISERROR(VLOOKUP(Y37,$E$2:$F$600,2, FALSE)),1,"") | AG37: =IF(ISERROR(VLOOKUP(E37,$Y$2:$Z$600,2,FALSE)),1,"") -> 1
E38: Bw Aries | F38: 84196 | G38: 54561 | H38: loaded | I38: Active | J38: 235106302 | K38: 9701786 | N38: TRUE | Y38: =IFERROR(__xludf.DUMMYFUNCTION("""COMPUTED_VALUE"""),"Gas Lagoon") -> Gas Lagoon | AC38: =IFERROR(__xludf.DUMMYFUNCTION("""COMPUTED_VALUE"""),"Bw Elm") -> Bw Elm | AE38: =IF(E38="","", IF(F38>93000,1,"")) | AF38: =IF(ISERROR(VLOOKUP(Y38,$E$2:$F$600,2, FALSE)),1,"") | AG38: =IF(ISERROR(VLOOKUP(E38,$Y$2:$Z$600,2,FALSE)),1,"") -> 1
E39: Bw Avior | F39: 91000 | G39: 62500 | H39: loaded | I39: Active | J39: 538010183 | K39: 9930296 | L39: Kashima | M39: 46131.875 | N39: TRUE | Y39: =IFERROR(__xludf.DUMMYFUNCTION("""COMPUTED_VALUE"""),"Gas Marakua") -> Gas Marakua | AC39: =IFERROR(__xludf.DUMMYFUNCTION("""COMPUTED_VALUE"""),"Bw Freyja") -> Bw Freyja | AE39: =IF(E39="","", IF(F39>93000,1,"")) | AF39: =IF(ISERROR(VLOOKUP(Y39,$E$2:$F$600,2, FALSE)),1,"") | AG39: =IF(ISERROR(VLOOKUP(E39,$Y$2:$Z$600,2,FALSE)),1,"") -> 1
E40: Bw Balder | F40: 84000 | G40: 54053 | H40: ballast | I40: Active | J40: 538006835 | K40: 9732527 | L40: Panama Canal | M40: 46135.542 | N40: FALSE | Y40: =IFERROR(__xludf.DUMMYFUNCTION("""COMPUTED_VALUE"""),"Gas Strength") -> Gas Strength | AC40: =IFERROR(__xludf.DUMMYFUNCTION("""COMPUTED_VALUE"""),"Bw Frigg") -> Bw Frigg | AE40: =IF(E40="","", IF(F40>93000,1,"")) | AF40: =IF(ISERROR(VLOOKUP(Y40,$E$2:$F$600,2, FALSE)),1,"") | AG40: =IF(ISERROR(VLOOKUP(E40,$Y$2:$Z$600,2,FALSE)),1,"") -> 1
...

Sheet 2) Tracker
K1: Laden | U1: What | V1: botan | Z1: With Waiting
A2: Vessel | B2: BLT | C2: CBM | D2: US | E2: Chinese | G2: Deck Tank | H2: Scrubber/Dual Fuel/Deck Tank | I2: Control | J2: AIS | K2: v Cape | L2: Position | M2: Open From | N2: Open To | P2: Notes: | Q2: Next loading: | R2: Voyage (no rate; + opts): | S2: Edited by: | T2: Updated | U2: Area | V2: AIS Location | W2: Date | X2: Status | Y2: ETA AG | Z2: ETA USG (P) | AA2: ETA USG (C) | AB2: ETA Bonny | AC2: Bethioua | AD2: ETA S'pore | AE2: ETA Darwin | AF2: ETA Yanbu | AG2: ETA AG | AH2: ETA AG 1 | AI2: ETA AG 2 | AJ2: ETA USG (P) | AK2: ETA USG1 | AL2: ETA USG2 | AM2: ETA USG (C) | AN2: ETA USG1 | AO2: ETA USG2 | AP2: ETA WAF | AQ2: ETA WAF1 | AR2: ETA WAF2 | AS2: ETA Bethouia | AT2: ETA Bethioua | AU2: ETA Bethioua | AV2: ETA WEST'PORT | AW2: ETA WEST'PORT 1 | AX2: ETA WEST'PORT 2 | AY2: ETA DARWIN | AZ2: ETA DARWIN1 | BA2: ETA DARWIN2 | BB2: ETA S'PORE | BC2: ETA SPORE1 | BD2: ETA SPORE2 | BE2: ETA P.Rupert | BF2: ETA P. Rupert 1 | BG2: ETA P. Rupert 2 | BH2: ETA Bonython | BI2: ETA Bonython | BJ2: ETA Yanbu | BK2: ETA Yanbu 1 | BL2: ETA Yanbu 2 | BM2: GOA Yanbu | BN2: ETA AG O | BO2: ETA USG O
A3: Astomos Venus | B3: 42460 | C3: 83000 | I3: AltaGas | J3: =IF(W3="","NO AIS",IF((W3-M3-1)>0,"Update","")) -> NO AIS | L3: Far East | M3: 46150 | N3: 46151 | P3: ex DD, ETA Ferndale 16 Apr | R3: Altagas 16-17 Apr Ferndale | S3: BR | T3: 46124 | U3: =IF(V3="","No AIS",VLOOKUP(V3,'Voyage days'!$A$3:$B$1480,2,FALSE)) -> No AIS | V3: =IF(VLOOKUP(A3,'1) Kpler'!$E$2:$P$1000,8, FALSE)="","",VLOOKUP(A3,'1) Kpler'!$E$2:$P$1000,8, FALSE)) | W3: =IF(VLOOKUP(A3,'1) Kpler'!$E$2:$P$1000,9,FALSE)="","",VLOOKUP(A3,'1) Kpler'!$E$2:$P$1000,9,FALSE)) | X3: =VLOOKUP(A3,'1) Kpler'!$E$2:$I$1000,4,FALSE) -> loaded | Y3: =AG3 -> 26-27 May | Z3: =AJ3 -> 08-09 Jun | AA3: =AM3 -> 15-16 Jun | AB3: =AP3 -> 07-08 Jun | AC3: =AS3 -> 13-14 Jun | AD3: =BB3 -> 16-17 May | AE3: =AY3 -> 16-17 May | AF3: =BJ3 -> 23-24 Jun | AG3: =IF(AH3="","",TEXT(AH3,"dd")&"-"&TEXT(AI3,"dd mmm")) -> 26-27 May | AH3: =IFERROR($M3+VLOOKUP($L3,'Voyage days'!$F$38:$H$89,3,FALSE),"") -> 46168 | AI3: =IFERROR(N3+VLOOKUP($L3,'Voyage days'!$F$38:$H$89,3,FALSE),"") -> 46169 | AJ3: =IF(AK3="","",TEXT(AK3,"dd")&"-"&TEXT(AL3,"dd mmm")) -> 08-09 Jun | AK3: =IFERROR($M3+VLOOKUP($L3,'Voyage days'!$F$94:$H$193,3,FALSE),"") -> 46181 | AL3: =IFERROR($N3+VLOOKUP($L3,'Voyage days'!$F$94:$H$193,3,FALSE),"") -> 46182 | AM3: =IF(AN3="","",TEXT(AN3,"dd")&"-"&TEXT(AO3,"dd mmm")) -> 15-16 Jun | AN3: =IFERROR($M3+VLOOKUP($L3,'Voyage days'!$F$203:$H$256,3,FALSE),"") -> 46188 | AO3: =IFERROR($N3+VLOOKUP($L3,'Voyage days'!$F$203:$H$256,3,FALSE),"") -> 46189 | AP3: =IF(AQ3="","",TEXT(AQ3,"dd")&"-"&TEXT(AR3,"dd mmm")) -> 07-08 Jun | AQ3: =IFERROR($M3+VLOOKUP($L3,'Voyage days'!$F$294:$H$377,3,FALSE),"") -> 46180 | AR3: =IFERROR($N3+VLOOKUP($L3,'Voyage days'!$F$294:$H$377,3,FALSE),"") -> 46181 | AS3: =IF(AT3="","",TEXT(AT3,"dd")&"-"&TEXT(AU3,"dd mmm")) -> 13-14 Jun | AT3: =IFERROR($M3+VLOOKUP($L3,'Voyage days'!$F$382:$H$446,3,FALSE),"") -> 46186 | AU3: =IFERROR($N3+VLOOKUP($L3,'Voyage days'!$F$382:$H$446,3,FALSE),"") -> 46187 | AV3: =IF(AW3="","",TEXT(AW3,"dd")&"-"&TEXT(AX3,"dd mmm")) -> 21-22 May | AW3: =IFERROR($M3+VLOOKUP($L3,'Voyage days'!$F$483:$H$538,3,FALSE),"") -> 46163 | AX3: =IFERROR($N3+VLOOKUP($L3,'Voyage days'!$F$483:$H$538,3,FALSE),"") -> 46164 | AY3: =IF(AZ3="","",TEXT(AZ3,"dd")&"-"&TEXT(BA3,"dd mmm")) -> 16-17 May | AZ3: =IFERROR($M3+VLOOKUP($L3,'Voyage days'!$F$540:$H$613,3,FALSE),"") -> 46158.25 | BA3: =IFERROR($N3+VLOOKUP($L3,'Voyage days'!$F$540:$H$613,3,FALSE),"") -> 46159.25 | BB3: =IF(BC3="","",TEXT(BC3,"dd")&"-"&TEXT(BD3,"dd mmm")) -> 16-17 May | BC3: =IFERROR($M3+VLOOKUP($L3,'Voyage days'!$F$448:$H$479,3,FALSE),"") -> 46158 | BD3: =IFERROR($N3+VLOOKUP($L3,'Voyage days'!$F$448:$H$479,3,FALSE),"") -> 46159 | BE3: =IF(BF3="","",TEXT(BF3,"dd")&"-"&TEXT(BG3,"dd mmm")) -> 19-20 May | BF3: =IFERROR($M3+VLOOKUP($L3,'Voyage days'!$F$620:$H$646,3,FALSE),"") -> 46161 | BG3: =IFERROR($N3+VLOOKUP($L3,'Voyage days'!$F$620:$H$646,3,FALSE),"") -> 46162 | BH3: =IF(BI3="","",TEXT(BI3,"dd")&"-"&TEXT(BL3,"dd mmm")) -> 16-24 Jun | BI3: =IFERROR($M3+VLOOKUP($L3,'Voyage days'!$F$702:$H$727,3,FALSE),"") -> 46158.25 | BJ3: =IF(BK3="","",TEXT(BK3,"dd")&"-"&TEXT(BL3,"dd mmm")) -> 23-24 Jun | BK3: =IFERROR($M3+VLOOKUP($L3,'Voyage days'!$F$807:$H$878,3,FALSE),"") -> 46196 | BL3: =IFERROR($N3+VLOOKUP($L3,'Voyage days'!$F$807:$H$878,3,FALSE),"") -> 46197 | BM3: =IFERROR($N3+VLOOKUP($L3,'Voyage days'!$F$807:$K$878,6,FALSE),"") -> 46171 | BN3: =if(L3="loads AG", IFERROR($M3+VLOOKUP($L3,'Voyage days'!$M$38:$O$38,3,FALSE),""),"") | BO3: =if(L3="loads USG", IFERROR($M3+VLOOKUP($L3,'Voyage days'!$L$203:$N$203,3,FALSE),""),"")
A4: Aurora Guardian | B4: 2026 | C4: 86665 | I4: AltaGas | J4: =IF(W4="","NO AIS",IF((W4-M4-1)>0,"Update","")) -> NO AIS | P4: New Build @ Japan | V4: =IF(VLOOKUP(A4,'1) Kpler'!$E$2:$P$1000,8, FALSE)="","",VLOOKUP(A4,'1) Kpler'!$E$2:$P$1000,8, FALSE)) | W4: =IF(VLOOKUP(A4,'1) Kpler'!$E$2:$P$1000,9,FALSE)="","",VLOOKUP(A4,'1) Kpler'!$E$2:$P$1000,9,FALSE)) | X4: =VLOOKUP(A4,'1) Kpler'!$E$2:$I$1000,4,FALSE) -> underConstruction | Y4: =AG4 | Z4: =AJ4 | AA4: =AM4 | AB4: =AP4 | AC4: =AS4 | AD4: =BB4 | AE4: =AY4 | AF4: =BJ4 | AG4: =IF(AH4="","",TEXT(AH4,"dd")&"-"&TEXT(AI4,"dd mmm")) | AH4: =IFERROR($M4+VLOOKUP($L4,'Voyage days'!$F$38:$H$89,3,FALSE),"") | AI4: =IFERROR(N4+VLOOKUP($L4,'Voyage days'!$F$38:$H$89,3,FALSE),"") | AJ4: =IF(AK4="","",TEXT(AK4,"dd")&"-"&TEXT(AL4,"dd mmm")) | AK4: =IFERROR($M4+VLOOKUP($L4,'Voyage days'!$F$94:$H$193,3,FALSE),"") | AL4: =IFERROR($N4+VLOOKUP($L4,'Voyage days'!$F$94:$H$193,3,FALSE),"") | AM4: =IF(AN4="","",TEXT(AN4,"dd")&"-"&TEXT(AO4,"dd mmm")) | AN4: =IFERROR($M4+VLOOKUP($L4,'Voyage days'!$F$203:$H$256,3,FALSE),"") | AO4: =IFERROR($N4+VLOOKUP($L4,'Voyage days'!$F$203:$H$256,3,FALSE),"") | AP4: =IF(AQ4="","",TEXT(AQ4,"dd")&"-"&TEXT(AR4,"dd mmm")) | AQ4: =IFERROR($M4+VLOOKUP($L4,'Voyage days'!$F$294:$H$377,3,FALSE),"") | AR4: =IFERROR($N4+VLOOKUP($L4,'Voyage days'!$F$294:$H$377,3,FALSE),"") | AS4: =IF(AT4="","",TEXT(AT4,"dd")&"-"&TEXT(AU4,"dd mmm")) | AT4: =IFERROR($M4+VLOOKUP($L4,'Voyage days'!$F$382:$H$446,3,FALSE),"") | AU4: =IFERROR($N4+VLOOKUP($L4,'Voyage days'!$F$382:$H$446,3,FALSE),"") | AV4: =IF(AW4="","",TEXT(AW4,"dd")&"-"&TEXT(AX4,"dd mmm")) | AW4: =IFERROR($M4+VLOOKUP($L4,'Voyage days'!$F$483:$H$538,3,FALSE),"") | AX4: =IFERROR($N4+VLOOKUP($L4,'Voyage days'!$F$483:$H$538,3,FALSE),"") | AY4: =IF(AZ4="","",TEXT(AZ4,"dd")&"-"&TEXT(BA4,"dd mmm")) | AZ4: =IFERROR($M4+VLOOKUP($L4,'Voyage days'!$F$540:$H$613,3,FALSE),"") | BA4: =IFERROR($N4+VLOOKUP($L4,'Voyage days'!$F$540:$H$613,3,FALSE),"") | BB4: =IF(BC4="","",TEXT(BC4,"dd")&"-"&TEXT(BD4,"dd mmm")) | BC4: =IFERROR($M4+VLOOKUP($L4,'Voyage days'!$F$448:$H$479,3,FALSE),"") | BD4: =IFERROR($N4+VLOOKUP($L4,'Voyage days'!$F$448:$H$479,3,FALSE),"") | BE4: =IF(BF4="","",TEXT(BF4,"dd")&"-"&TEXT(BG4,"dd mmm")) | BF4: =IFERROR($M4+VLOOKUP($L4,'Voyage days'!$F$620:$H$646,3,FALSE),"") | BG4: =IFERROR($N4+VLOOKUP($L4,'Voyage days'!$F$620:$H$646,3,FALSE),"") | BH4: =IF(BI4="","",TEXT(BI4,"dd")&"-"&TEXT(BL4,"dd mmm")) | BI4: =IFERROR($M4+VLOOKUP($L4,'Voyage days'!$F$702:$H$727,3,FALSE),"") | BJ4: =IF(BK4="","",TEXT(BK4,"dd")&"-"&TEXT(BL4,"dd mmm")) | BK4: =IFERROR($M4+VLOOKUP($L4,'Voyage days'!$F$807:$H$878,3,FALSE),"") | BL4: =IFERROR($N4+VLOOKUP($L4,'Voyage days'!$F$807:$H$878,3,FALSE),"") | BM4: =IFERROR($N4+VLOOKUP($L4,'Voyage days'!$F$807:$K$878,6,FALSE),"") | BN4: =if(L4="loads AG", IFERROR($M4+VLOOKUP($L4,'Voyage days'!$M$38:$O$38,3,FALSE),""),"") | BO4: =if(L4="loads USG", IFERROR($M4+VLOOKUP($L4,'Voyage days'!$L$203:$N$203,3,FALSE),""),"")
A5: Boreal Pioneer | B5: 2023 | C5: 91000 | I5: AltaGas | J5: =IF(W5="","NO AIS",IF((W5-M5-1)>0,"Update","")) | L5: Far East | M5: 46155 | N5: 46156 | P5: ETA Prince Rupert 23 Apr | R5: Altagas 23 Mar RIPET | S5: BR | T5: 46124 | U5: =IF(V5="","No AIS",VLOOKUP(V5,'Voyage days'!$A$3:$B$1480,2,FALSE)) -> +14 days to Far East | V5: =IF(VLOOKUP(A5,'1) Kpler'!$E$2:$P$1000,8, FALSE)="","",VLOOKUP(A5,'1) Kpler'!$E$2:$P$1000,8, FALSE)) -> RIPET | W5: =IF(VLOOKUP(A5,'1) Kpler'!$E$2:$P$1000,9,FALSE)="","",VLOOKUP(A5,'1) Kpler'!$E$2:$P$1000,9,FALSE)) -> 46135.125 | X5: =VLOOKUP(A5,'1) Kpler'!$E$2:$I$1000,4,FALSE) -> ballast | Y5: =AG5 -> 31-01 Jun | Z5: =AJ5 -> 13-14 Jun | AA5: =AM5 -> 20-21 Jun | AB5: =AP5 -> 12-13 Jun | AC5: =AS5 -> 18-19 Jun | AD5: =BB5 -> 21-22 May | AE5: =AY5 -> 21-22 May | AF5: =BJ5 -> 28-29 Jun | AG5: =IF(AH5="","",TEXT(AH5,"dd")&"-"&TEXT(AI5,"dd mmm")) -> 31-01 Jun | AH5: =IFERROR($M5+VLOOKUP($L5,'Voyage days'!$F$38:$H$89,3,FALSE),"") -> 46173 | AI5: =IFERROR(N5+VLOOKUP($L5,'Voyage days'!$F$38:$H$89,3,FALSE),"") -> 46174 | AJ5: =IF(AK5="","",TEXT(AK5,"dd")&"-"&TEXT(AL5,"dd mmm")) -> 13-14 Jun | AK5: =IFERROR($M5+VLOOKUP($L5,'Voyage days'!$F$94:$H$193,3,FALSE),"") -> 46186 | AL5: =IFERROR($N5+VLOOKUP($L5,'Voyage days'!$F$94:$H$193,3,FALSE),"") -> 46187 | AM5: =IF(AN5="","",TEXT(AN5,"dd")&"-"&TEXT(AO5,"dd mmm")) -> 20-21 Jun | AN5: =IFERROR($M5+VLOOKUP($L5,'Voyage days'!$F$203:$H$256,3,FALSE),"") -> 46193 | AO5: =IFERROR($N5+VLOOKUP($L5,'Voyage days'!$F$203:$H$256,3,FALSE),"") -> 46194 | AP5: =IF(AQ5="","",TEXT(AQ5,"dd")&"-"&TEXT(AR5,"dd mmm")) -> 12-13 Jun | AQ5: =IFERROR($M5+VLOOKUP($L5,'Voyage days'!$F$294:$H$377,3,FALSE),"") -> 46185 | AR5: =IFERROR($N5+VLOOKUP($L5,'Voyage days'!$F$294:$H$377,3,FALSE),"") -> 46186 | AS5: =IF(AT5="","",TEXT(AT5,"dd")&"-"&TEXT(AU5,"dd mmm")) -> 18-19 Jun | AT5: =IFERROR($M5+VLOOKUP($L5,'Voyage days'!$F$382:$H$446,3,FALSE),"") -> 46191 | AU5: =IFERROR($N5+VLOOKUP($L5,'Voyage days'!$F$382:$H$446,3,FALSE),"") -> 46192 | AV5: =IF(AW5="","",TEXT(AW5,"dd")&"-"&TEXT(AX5,"dd mmm")) -> 26-27 May | AW5: =IFERROR($M5+VLOOKUP($L5,'Voyage days'!$F$483:$H$538,3,FALSE),"") -> 46168 | AX5: =IFERROR($N5+VLOOKUP($L5,'Voyage days'!$F$483:$H$538,3,FALSE),"") -> 46169 | AY5: =IF(AZ5="","",TEXT(AZ5,"dd")&"-"&TEXT(BA5,"dd mmm")) -> 21-22 May | AZ5: =IFERROR($M5+VLOOKUP($L5,'Voyage days'!$F$540:$H$613,3,FALSE),"") -> 46163.25 | BA5: =IFERROR($N5+VLOOKUP($L5,'Voyage days'!$F$540:$H$613,3,FALSE),"") -> 46164.25 | BB5: =IF(BC5="","",TEXT(BC5,"dd")&"-"&TEXT(BD5,"dd mmm")) -> 21-22 May | BC5: =IFERROR($M5+VLOOKUP($L5,'Voyage days'!$F$448:$H$479,3,FALSE),"") -> 46163 | BD5: =IFERROR($N5+VLOOKUP($L5,'Voyage days'!$F$448:$H$479,3,FALSE),"") -> 46164 | BE5: =IF(BF5="","",TEXT(BF5,"dd")&"-"&TEXT(BG5,"dd mmm")) -> 24-25 May | BF5: =IFERROR($M5+VLOOKUP($L5,'Voyage days'!$F$620:$H$646,3,FALSE),"") -> 46166 | BG5: =IFERROR($N5+VLOOKUP($L5,'Voyage days'!$F$620:$H$646,3,FALSE),"") -> 46167 | BH5: =IF(BI5="","",TEXT(BI5,"dd")&"-"&TEXT(BL5,"dd mmm")) -> 21-29 Jun | BI5: =IFERROR($M5+VLOOKUP($L5,'Voyage days'!$F$702:$H$727,3,FALSE),"") -> 46163.25 | BJ5: =IF(BK5="","",TEXT(BK5,"dd")&"-"&TEXT(BL5,"dd mmm")) -> 28-29 Jun | BK5: =IFERROR($M5+VLOOKUP($L5,'Voyage days'!$F$807:$H$878,3,FALSE),"") -> 46201 | BL5: =IFERROR($N5+VLOOKUP($L5,'Voyage days'!$F$807:$H$878,3,FALSE),"") -> 46202 | BM5: =IFERROR($N5+VLOOKUP($L5,'Voyage days'!$F$807:$K$878,6,FALSE),"") -> 46176 | BN5: =if(L5="loads AG", IFERROR($M5+VLOOKUP($L5,'Voyage days'!$M$38:$O$38,3,FALSE),""),"") | BO5: =if(L5="loads USG", IFERROR($M5+VLOOKUP($L5,'Voyage days'!$L$203:$N$203,3,FALSE),""),"")
A6: Boreal Voyager | B6: 2024 | C6: 91000 | I6: AltaGas | J6: =IF(W6="","NO AIS",IF((W6-M6-1)>0,"Update","")) | L6: East China | M6: 46137 | N6: 46138 | P6: ETA Jiangyin 21 Apr | R6: Altagas 05 Apr RIPET | S6: BR | T6: 46124 | U6: =IF(V6="","No AIS",VLOOKUP(V6,'Voyage days'!$A$3:$B$1480,2,FALSE)) -> East China + 4 | V6: =IF(VLOOKUP(A6,'1) Kpler'!$E$2:$P$1000,8, FALSE)="","",VLOOKUP(A6,'1) Kpler'!$E$2:$P$1000,8, FALSE)) -> Wenzhou | W6: =IF(VLOOKUP(A6,'1) Kpler'!$E$2:$P$1000,9,FALSE)="","",VLOOKUP(A6,'1) Kpler'!$E$2:$P$1000,9,FALSE)) -> 46132.708 | X6: =VLOOKUP(A6,'1) Kpler'!$E$2:$I$1000,4,FALSE) -> loaded | Y6: =AG6 -> 12-13 May | Z6: =AJ6 -> 28-29 May | AA6: =AM6 -> 08-09 Jun | AB6: =AP6 -> 23-24 May | AC6: =AS6 -> 30-31 May | AD6: =BB6 -> 01-02 May | AE6: =AY6 -> 02-03 May | AF6: =BJ6 -> 08-09 Jun | AG6: =IF(AH6="","",TEXT(AH6,"dd")&"-"&TEXT(AI6,"dd mmm")) -> 12-13 May | AH6: =IFERROR($M6+VLOOKUP($L6,'Voyage days'!$F$38:$H$89,3,FALSE),"") -> 46154 | AI6: =IFERROR(N6+VLOOKUP($L6,'Voyage days'!$F$38:$H$89,3,FALSE),"") -> 46155 | AJ6: =IF(AK6="","",TEXT(AK6,"dd")&"-"&TEXT(AL6,"dd mmm")) -> 28-29 May | AK6: =IFERROR($M6+VLOOKUP($L6,'Voyage days'!$F$94:$H$193,3,FALSE),"") -> 46170 | AL6: =IFERROR($N6+VLOOKUP($L6,'Voyage days'!$F$94:$H$193,3,FALSE),"") -> 46171 | AM6: =IF(AN6="","",TEXT(AN6,"dd")&"-"&TEXT(AO6,"dd mmm")) -> 08-09 Jun | AN6: =IFERROR($M6+VLOOKUP($L6,'Voyage days'!$F$203:$H$256,3,FALSE),"") -> 46181 | AO6: =IFERROR($N6+VLOOKUP($L6,'Voyage days'!$F$203:$H$256,3,FALSE),"") -> 46182 | AP6: =IF(AQ6="","",TEXT(AQ6,"dd")&"-"&TEXT(AR6,"dd mmm")) -> 23-24 May | AQ6: =IFERROR($M6+VLOOKUP($L6,'Voyage days'!$F$294:$H$377,3,FALSE),"") -> 46165 | AR6: =IFERROR($N6+VLOOKUP($L6,'Voyage days'!$F$294:$H$377,3,FALSE),"") -> 46166 | AS6: =IF(AT6="","",TEXT(AT6,"dd")&"-"&TEXT(AU6,"dd mmm")) -> 30-31 May | AT6: =IFERROR($M6+VLOOKUP($L6,'Voyage days'!$F$382:$H$446,3,FALSE),"") -> 46172 | AU6: =IFERROR($N6+VLOOKUP($L6,'Voyage days'!$F$382:$H$446,3,FALSE),"") -> 46173 | AV6: =IF(AW6="","",TEXT(AW6,"dd")&"-"&TEXT(AX6,"dd mmm")) -> 09-10 May | AW6: =IFERROR($M6+VLOOKUP($L6,'Voyage days'!$F$483:$H$538,3,FALSE),"") -> 46151 | AX6: =IFERROR($N6+VLOOKUP($L6,'Voyage days'!$F$483:$H$538,3,FALSE),"") -> 46152 | AY6: =IF(AZ6="","",TEXT(AZ6,"dd")&"-"&TEXT(BA6,"dd mmm")) -> 02-03 May | AZ6: =IFERROR($M6+VLOOKUP($L6,'Voyage days'!$F$540:$H$613,3,FALSE),"") -> 46144.25 | BA6: =IFERROR($N6+VLOOKUP($L6,'Voyage days'!$F$540:$H$613,3,FALSE),"") -> 46145.25 | BB6: =IF(BC6="","",TEXT(BC6,"dd")&"-"&TEXT(BD6,"dd mmm")) -> 01-02 May | BC6: =IFERROR($M6+VLOOKUP($L6,'Voyage days'!$F$448:$H$479,3,FALSE),"") -> 46143 | BD6: =IFERROR($N6+VLOOKUP($L6,'Voyage days'!$F$448:$H$479,3,FALSE),"") -> 46144 | BE6: =IF(BF6="","",TEXT(BF6,"dd")&"-"&TEXT(BG6,"dd mmm")) -> 08-09 May | BF6: =IFERROR($M6+VLOOKUP($L6,'Voyage days'!$F$620:$H$646,3,FALSE),"") -> 46150 | BG6: =IFERROR($N6+VLOOKUP($L6,'Voyage days'!$F$620:$H$646,3,FALSE),"") -> 46151 | BH6: =IF(BI6="","",TEXT(BI6,"dd")&"-"&TEXT(BL6,"dd mmm")) -> 02-09 Jun | BI6: =IFERROR($M6+VLOOKUP($L6,'Voyage days'!$F$702:$H$727,3,FALSE),"") -> 46144.25 | BJ6: =IF(BK6="","",TEXT(BK6,"dd")&"-"&TEXT(BL6,"dd mmm")) -> 08-09 Jun | BK6: =IFERROR($M6+VLOOKUP($L6,'Voyage days'!$F$807:$H$878,3,FALSE),"") -> 46181 | BL6: =IFERROR($N6+VLOOKUP($L6,'Voyage days'!$F$807:$H$878,3,FALSE),"") -> 46182 | BM6: =IFERROR($N6+VLOOKUP($L6,'Voyage days'!$F$807:$K$878,6,FALSE),"") -> 46156 | BN6: =if(L6="loads AG", IFERROR($M6+VLOOKUP($L6,'Voyage days'!$M$38:$O$38,3,FALSE),""),"") | BO6: =if(L6="loads USG", IFERROR($M6+VLOOKUP($L6,'Voyage days'!$L$203:$N$203,3,FALSE),""),"")
A7: Gas Amethyst | B7: 2024 | C7: 86700 | H7: DF | I7: Astomos | J7: =IF(W7="","NO AIS",IF((W7-M7-1)>0,"Update","")) | L7: Japan | M7: 46152 | N7: 46153 | P7: ETA Nagoya 04 May | R7: Astomos 29-30 Mar Freeport | S7: BR | T7: 46124 | U7: =IF(V7="","No AIS",VLOOKUP(V7,'Voyage days'!$A$3:$B$1480,2,FALSE)) -> Japan + 6 | V7: =IF(VLOOKUP(A7,'1) Kpler'!$E$2:$P$1000,8, FALSE)="","",VLOOKUP(A7,'1) Kpler'!$E$2:$P$1000,8, FALSE)) -> Nagoya | W7: =IF(VLOOKUP(A7,'1) Kpler'!$E$2:$P$1000,9,FALSE)="","",VLOOKUP(A7,'1) Kpler'!$E$2:$P$1000,9,FALSE)) -> 46146.125 | X7: =VLOOKUP(A7,'1) Kpler'!$E$2:$I$1000,4,FALSE) -> loaded | Y7: =AG7 -> 28-29 May | Z7: =AJ7 -> 11-12 Jun | AA7: =AM7 -> 21-22 Jun | AB7: =AP7 -> 09-10 Jun | AC7: =AS7 -> 15-16 Jun | AD7: =BB7 -> 18-19 May | AE7: =AY7 -> 18-19 May | AF7: =BJ7 -> 25-26 Jun | AG7: =IF(AH7="","",TEXT(AH7,"dd")&"-"&TEXT(AI7,"dd mmm")) -> 28-29 May | AH7: =IFERROR($M7+VLOOKUP($L7,'Voyage days'!$F$38:$H$89,3,FALSE),"") -> 46170 | AI7: =IFERROR(N7+VLOOKUP($L7,'Voyage days'!$F$38:$H$89,3,FALSE),"") -> 46171 | AJ7: =IF(AK7="","",TEXT(AK7,"dd")&"-"&TEXT(AL7,"dd mmm")) -> 11-12 Jun | AK7: =IFERROR($M7+VLOOKUP($L7,'Voyage days'!$F$94:$H$193,3,FALSE),"") -> 46184 | AL7: =IFERROR($N7+VLOOKUP($L7,'Voyage days'!$F$94:$H$193,3,FALSE),"") -> 46185 | AM7: =IF(AN7="","",TEXT(AN7,"dd")&"-"&TEXT(AO7,"dd mmm")) -> 21-22 Jun | AN7: =IFERROR($M7+VLOOKUP($L7,'Voyage days'!$F$203:$H$256,3,FALSE),"") -> 46194 | AO7: =IFERROR($N7+VLOOKUP($L7,'Voyage days'!$F$203:$H$256,3,FALSE),"") -> 46195 | AP7: =IF(AQ7="","",TEXT(AQ7,"dd")&"-"&TEXT(AR7,"dd mmm")) -> 09-10 Jun | AQ7: =IFERROR($M7+VLOOKUP($L7,'Voyage days'!$F$294:$H$377,3,FALSE),"") -> 46182 | AR7: =IFERROR($N7+VLOOKUP($L7,'Voyage days'!$F$294:$H$377,3,FALSE),"") -> 46183 | AS7: =IF(AT7="","",TEXT(AT7,"dd")&"-"&TEXT(AU7,"dd mmm")) -> 15-16 Jun | AT7: =IFERROR($M7+VLOOKUP($L7,'Voyage days'!$F$382:$H$446,3,FALSE),"") -> 46188 | AU7: =IFERROR($N7+VLOOKUP($L7,'Voyage days'!$F$382:$H$446,3,FALSE),"") -> 46189 | AV7: =IF(AW7="","",TEXT(AW7,"dd")&"-"&TEXT(AX7,"dd mmm")) -> 23-24 May | AW7: =IFERROR($M7+VLOOKUP($L7,'Voyage days'!$F$483:$H$538,3,FALSE),"") -> 46165 | AX7: =IFERROR($N7+VLOOKUP($L7,'Voyage days'!$F$483:$H$538,3,FALSE),"") -> 46166 | AY7: =IF(AZ7="","",TEXT(AZ7,"dd")&"-"&TEXT(BA7,"dd mmm")) -> 18-19 May | AZ7: =IFERROR($M7+VLOOKUP($L7,'Voyage days'!$F$540:$H$613,3,FALSE),"") -> 46160.25 | BA7: =IFERROR($N7+VLOOKUP($L7,'Voyage days'!$F$540:$H$613,3,FALSE),"") -> 46161.25 | BB7: =IF(BC7="","",TEXT(BC7,"dd")&"-"&TEXT(BD7,"dd mmm")) -> 18-19 May | BC7: =IFERROR($M7+VLOOKUP($L7,'Voyage days'!$F$448:$H$479,3,FALSE),"") -> 46160 | BD7: =IFERROR($N7+VLOOKUP($L7,'Voyage days'!$F$448:$H$479,3,FALSE),"") -> 46161 | BE7: =IF(BF7="","",TEXT(BF7,"dd")&"-"&TEXT(BG7,"dd mmm")) -> 21-22 May | BF7: =IFERROR($M7+VLOOKUP($L7,'Voyage days'!$F$620:$H$646,3,FALSE),"") -> 46163 | BG7: =IFERROR($N7+VLOOKUP($L7,'Voyage days'!$F$620:$H$646,3,FALSE),"") -> 46164 | BH7: =IF(BI7="","",TEXT(BI7,"dd")&"-"&TEXT(BL7,"dd mmm")) -> 18-26 Jun | BI7: =IFERROR($M7+VLOOKUP($L7,'Voyage days'!$F$702:$H$727,3,FALSE),"") -> 46160.25 | BJ7: =IF(BK7="","",TEXT(BK7,"dd")&"-"&TEXT(BL7,"dd mmm")) -> 25-26 Jun | BK7: =IFERROR($M7+VLOOKUP($L7,'Voyage days'!$F$807:$H$878,3,FALSE),"") -> 46198 | BL7: =IFERROR($N7+VLOOKUP($L7,'Voyage days'!$F$807:$H$878,3,FALSE),"") -> 46199 | BM7: =IFERROR($N7+VLOOKUP($L7,'Voyage days'!$F$807:$K$878,6,FALSE),"") -> 46173 | BN7: =if(L7="loads AG", IFERROR($M7+VLOOKUP($L7,'Voyage days'!$M$38:$O$38,3,FALSE),""),"") | BO7: =if(L7="loads USG", IFERROR($M7+VLOOKUP($L7,'Voyage days'!$L$203:$N$203,3,FALSE),""),"")
A8: Gas Capricorn | B8: 37773 | C8: 78934 | I8: Astomos | J8: =IF(W8="","NO AIS",IF((W8-M8-1)>0,"Update","")) -> Update | L8: Cape ballast | M8: 46125 | N8: 46126 | P8: ETA USG 04 May via Cape | R8: Astomos 24-25 Jan Ras Laffan | S8: BR | T8: 46124 | U8: =IF(V8="","No AIS",VLOOKUP(V8,'Voyage days'!$A$3:$B$1480,2,FALSE)) -> USG | V8: =IF(VLOOKUP(A8,'1) Kpler'!$E$2:$P$1000,8, FALSE)="","",VLOOKUP(A8,'1) Kpler'!$E$2:$P$1000,8, FALSE)) -> Houston | W8: =IF(VLOOKUP(A8,'1) Kpler'!$E$2:$P$1000,9,FALSE)="","",VLOOKUP(A8,'1) Kpler'!$E$2:$P$1000,9,FALSE)) -> 46146.125 | X8: =VLOOKUP(A8,'1) Kpler'!$E$2:$I$1000,4,FALSE) -> ballast | Y8: =AG8 | Z8: =AJ8 | AA8: =AM8 -> 04-05 May | AB8: =AP8 -> 23-24 Apr | AC8: =AS8 -> 29-30 Apr | AD8: =BB8 -> 29-30 Apr | AE8: =AY8 | AF8: =BJ8 -> 06-07 May | AG8: =IF(AH8="","",TEXT(AH8,"dd")&"-"&TEXT(AI8,"dd mmm")) | AH8: =IFERROR($M8+VLOOKUP($L8,'Voyage days'!$F$38:$H$89,3,FALSE),"") | AI8: =IFERROR(N8+VLOOKUP($L8,'Voyage days'!$F$38:$H$89,3,FALSE),"") | AJ8: =IF(AK8="","",TEXT(AK8,"dd")&"-"&TEXT(AL8,"dd mmm")) | AK8: =IFERROR($M8+VLOOKUP($L8,'Voyage days'!$F$94:$H$193,3,FALSE),"") | AL8: =IFERROR($N8+VLOOKUP($L8,'Voyage days'!$F$94:$H$193,3,FALSE),"") | AM8: =IF(AN8="","",TEXT(AN8,"dd")&"-"&TEXT(AO8,"dd mmm")) -> 04-05 May | AN8: =IFERROR($M8+VLOOKUP($L8,'Voyage days'!$F$203:$H$256,3,FALSE),"") -> 46146 | AO8: =IFERROR($N8+VLOOKUP($L8,'Voyage days'!$F$203:$H$256,3,FALSE),"") -> 46147 | AP8: =IF(AQ8="","",TEXT(AQ8,"dd")&"-"&TEXT(AR8,"dd mmm")) -> 23-24 Apr | AQ8: =IFERROR($M8+VLOOKUP($L8,'Voyage days'!$F$294:$H$377,3,FALSE),"") -> 46135 | AR8: =IFERROR($N8+VLOOKUP($L8,'Voyage days'!$F$294:$H$377,3,FALSE),"") -> 46136 | AS8: =IF(AT8="","",TEXT(AT8,"dd")&"-"&TEXT(AU8,"dd mmm")) -> 29-30 Apr | AT8: =IFERROR($M8+VLOOKUP($L8,'Voyage days'!$F$382:$H$446,3,FALSE),"") -> 46141 | AU8: =IFERROR($N8+VLOOKUP($L8,'Voyage days'!$F$382:$H$446,3,FALSE),"") -> 46142 | AV8: =IF(AW8="","",TEXT(AW8,"dd")&"-"&TEXT(AX8,"dd mmm")) | AW8: =IFERROR($M8+VLOOKUP($L8,'Voyage days'!$F$483:$H$538,3,FALSE),"") | AX8: =IFERROR($N8+VLOOKUP($L8,'Voyage days'!$F$483:$H$538,3,FALSE),"") | AY8: =IF(AZ8="","",TEXT(AZ8,"dd")&"-"&TEXT(BA8,"dd mmm")) | AZ8: =IFERROR($M8+VLOOKUP($L8,'Voyage days'!$F$540:$H$613,3,FALSE),"") | BA8: =IFERROR($N8+VLOOKUP($L8,'Voyage days'!$F$540:$H$613,3,FALSE),"") | BB8: =IF(BC8="","",TEXT(BC8,"dd")&"-"&TEXT(BD8,"dd mmm")) -> 29-30 Apr | BC8: =IFERROR($M8+VLOOKUP($L8,'Voyage days'!$F$448:$H$479,3,FALSE),"") -> 46141 | BD8: =IFERROR($N8+VLOOKUP($L8,'Voyage days'!$F$448:$H$479,3,FALSE),"") -> 46142 | BE8: =IF(BF8="","",TEXT(BF8,"dd")&"-"&TEXT(BG8,"dd mmm")) | BF8: =IFERROR($M8+VLOOKUP($L8,'Voyage days'!$F$620:$H$646,3,FALSE),"") | BG8: =IFERROR($N8+VLOOKUP($L8,'Voyage days'!$F$620:$H$646,3,FALSE),"") | BH8: =IF(BI8="","",TEXT(BI8,"dd")&"-"&TEXT(BL8,"dd mmm")) | BI8: =IFERROR($M8+VLOOKUP($L8,'Voyage days'!$F$702:$H$727,3,FALSE),"") | BJ8: =IF(BK8="","",TEXT(BK8,"dd")&"-"&TEXT(BL8,"dd mmm")) -> 06-07 May | BK8: =IFERROR($M8+VLOOKUP($L8,'Voyage days'!$F$807:$H$878,3,FALSE),"") -> 46148 | BL8: =IFERROR($N8+VLOOKUP($L8,'Voyage days'!$F$807:$H$878,3,FALSE),"") -> 46149 | BM8: =IFERROR($N8+VLOOKUP($L8,'Voyage days'!$F$807:$K$878,6,FALSE),"") -> 46126 | BN8: =if(L8="loads AG", IFERROR($M8+VLOOKUP($L8,'Voyage days'!$M$38:$O$38,3,FALSE),""),"") | BO8: =if(L8="loads USG", IFERROR($M8+VLOOKUP($L8,'Voyage days'!$L$203:$N$203,3,FALSE),""),"")
A9: Kodaijisan | B9: 37895 | C9: 82000 | I9: Astomos | J9: =IF(W9="","NO AIS",IF((W9-M9-1)>0,"Update","")) -> NO AIS | L9: Honolulu | M9: 46124 | N9: 46125 | P9: ex DD, @ Honolulu 11 Apr | R9: Astomos 25-26 Dec Ras Laffan | S9: BR | T9: 46124 | U9: =IF(V9="","No AIS",VLOOKUP(V9,'Voyage days'!$A$3:$B$1480,2,FALSE)) -> No AIS | V9: =IF(VLOOKUP(A9,'1) Kpler'!$E$2:$P$1000,8, FALSE)="","",VLOOKUP(A9,'1) Kpler'!$E$2:$P$1000,8, FALSE)) | W9: =IF(VLOOKUP(A9,'1) Kpler'!$E$2:$P$1000,9,FALSE)="","",VLOOKUP(A9,'1) Kpler'!$E$2:$P$1000,9,FALSE)) | X9: =VLOOKUP(A9,'1) Kpler'!$E$2:$I$1000,4,FALSE) -> ballast | Y9: =AG9 | Z9: =AJ9 -> 29-30 Apr | AA9: =AM9 | AB9: =AP9 | AC9: =AS9 | AD9: =BB9 | AE9: =AY9 | AF9: =BJ9 | AG9: =IF(AH9="","",TEXT(AH9,"dd")&"-"&TEXT(AI9,"dd mmm")) | AH9: =IFERROR($M9+VLOOKUP($L9,'Voyage days'!$F$38:$H$89,3,FALSE),"") | AI9: =IFERROR(N9+VLOOKUP($L9,'Voyage days'!$F$38:$H$89,3,FALSE),"") | AJ9: =IF(AK9="","",TEXT(AK9,"dd")&"-"&TEXT(AL9,"dd mmm")) -> 29-30 Apr | AK9: =IFERROR($M9+VLOOKUP($L9,'Voyage days'!$F$94:$H$193,3,FALSE),"") -> 46141 | AL9: =IFERROR($N9+VLOOKUP($L9,'Voyage days'!$F$94:$H$193,3,FALSE),"") -> 46142 | AM9: =IF(AN9="","",TEXT(AN9,"dd")&"-"&TEXT(AO9,"dd mmm")) | AN9: =IFERROR($M9+VLOOKUP($L9,'Voyage days'!$F$203:$H$256,3,FALSE),"") | AO9: =IFERROR($N9+VLOOKUP($L9,'Voyage days'!$F$203:$H$256,3,FALSE),"") | AP9: =IF(AQ9="","",TEXT(AQ9,"dd")&"-"&TEXT(AR9,"dd mmm")) | AQ9: =IFERROR($M9+VLOOKUP($L9,'Voyage days'!$F$294:$H$377,3,FALSE),"") | AR9: =IFERROR($N9+VLOOKUP($L9,'Voyage days'!$F$294:$H$377,3,FALSE),"") | AS9: =IF(AT9="","",TEXT(AT9,"dd")&"-"&TEXT(AU9,"dd mmm")) | AT9: =IFERROR($M9+VLOOKUP($L9,'Voyage days'!$F$382:$H$446,3,FALSE),"") | AU9: =IFERROR($N9+VLOOKUP($L9,'Voyage days'!$F$382:$H$446,3,FALSE),"") | AV9: =IF(AW9="","",TEXT(AW9,"dd")&"-"&TEXT(AX9,"dd mmm")) | AW9: =IFERROR($M9+VLOOKUP($L9,'Voyage days'!$F$483:$H$538,3,FALSE),"") | AX9: =IFERROR($N9+VLOOKUP($L9,'Voyage days'!$F$483:$H$538,3,FALSE),"") | AY9: =IF(AZ9="","",TEXT(AZ9,"dd")&"-"&TEXT(BA9,"dd mmm")) | AZ9: =IFERROR($M9+VLOOKUP($L9,'Voyage days'!$F$540:$H$613,3,FALSE),"") | BA9: =IFERROR($N9+VLOOKUP($L9,'Voyage days'!$F$540:$H$613,3,FALSE),"") | BB9: =IF(BC9="","",TEXT(BC9,"dd")&"-"&TEXT(BD9,"dd mmm")) | BC9: =IFERROR($M9+VLOOKUP($L9,'Voyage days'!$F$448:$H$479,3,FALSE),"") | BD9: =IFERROR($N9+VLOOKUP($L9,'Voyage days'!$F$448:$H$479,3,FALSE),"") | BE9: =IF(BF9="","",TEXT(BF9,"dd")&"-"&TEXT(BG9,"dd mmm")) | BF9: =IFERROR($M9+VLOOKUP($L9,'Voyage days'!$F$620:$H$646,3,FALSE),"") | BG9: =IFERROR($N9+VLOOKUP($L9,'Voyage days'!$F$620:$H$646,3,FALSE),"") | BH9: =IF(BI9="","",TEXT(BI9,"dd")&"-"&TEXT(BL9,"dd mmm")) | BI9: =IFERROR($M9+VLOOKUP($L9,'Voyage days'!$F$702:$H$727,3,FALSE),"") | BJ9: =IF(BK9="","",TEXT(BK9,"dd")&"-"&TEXT(BL9,"dd mmm")) | BK9: =IFERROR($M9+VLOOKUP($L9,'Voyage days'!$F$807:$H$878,3,FALSE),"") | BL9: =IFERROR($N9+VLOOKUP($L9,'Voyage days'!$F$807:$H$878,3,FALSE),"") | BM9: =IFERROR($N9+VLOOKUP($L9,'Voyage days'!$F$807:$K$878,6,FALSE),"") | BN9: =if(L9="loads AG", IFERROR($M9+VLOOKUP($L9,'Voyage days'!$M$38:$O$38,3,FALSE),""),"") | BO9: =if(L9="loads USG", IFERROR($M9+VLOOKUP($L9,'Voyage days'!$L$203:$N$203,3,FALSE),""),"")
A10: Lantana Planet | B10: 2023 | C10: 84000 | H10: DF | I10: Astomos | J10: =IF(W10="","NO AIS",IF((W10-M10-1)>0,"Update","")) -> Update | L10: Balboa | M10: 46143 | N10: 46144 | P10: ETA Balboa 01 May | R10: Marathon 22-23 Feb Freeport | S10: BR | T10: 46124 | U10: =IF(V10="","No AIS",VLOOKUP(V10,'Voyage days'!$A$3:$B$1480,2,FALSE)) -> Panama | V10: =IF(VLOOKUP(A10,'1) Kpler'!$E$2:$P$1000,8, FALSE)="","",VLOOKUP(A10,'1) Kpler'!$E$2:$P$1000,8, FALSE)) -> Panama Canal | W10: =IF(VLOOKUP(A10,'1) Kpler'!$E$2:$P$1000,9,FALSE)="","",VLOOKUP(A10,'1) Kpler'!$E$2:$P$1000,9,FALSE)) -> 46145.708 | X10: =VLOOKUP(A10,'1) Kpler'!$E$2:$I$1000,4,FALSE) -> ballast | Y10: =AG10 | Z10: =AJ10 -> 12-13 May | AA10: =AM10 | AB10: =AP10 | AC10: =AS10 | AD10: =BB10 | AE10: =AY10 | AF10: =BJ10 | AG10: =IF(AH10="","",TEXT(AH10,"dd")&"-"&TEXT(AI10,"dd mmm")) | AH10: =IFERROR($M10+VLOOKUP($L10,'Voyage days'!$F$38:$H$89,3,FALSE),"") | AI10: =IFERROR(N10+VLOOKUP($L10,'Voyage days'!$F$38:$H$89,3,FALSE),"") | AJ10: =IF(AK10="","",TEXT(AK10,"dd")&"-"&TEXT(AL10,"dd mmm")) -> 12-13 May | AK10: =IFERROR($M10+VLOOKUP($L10,'Voyage days'!$F$94:$H$193,3,FALSE),"") -> 46154 | AL10: =IFERROR($N10+VLOOKUP($L10,'Voyage days'!$F$94:$H$193,3,FALSE),"") -> 46155 | AM10: =IF(AN10="","",TEXT(AN10,"dd")&"-"&TEXT(AO10,"dd mmm")) | AN10: =IFERROR($M10+VLOOKUP($L10,'Voyage days'!$F$203:$H$256,3,FALSE),"") | AO10: =IFERROR($N10+VLOOKUP($L10,'Voyage days'!$F$203:$H$256,3,FALSE),"") | AP10: =IF(AQ10="","",TEXT(AQ10,"dd")&"-"&TEXT(AR10,"dd mmm")) | AQ10: =IFERROR($M10+VLOOKUP($L10,'Voyage days'!$F$294:$H$377,3,FALSE),"") | AR10: =IFERROR($N10+VLOOKUP($L10,'Voyage days'!$F$294:$H$377,3,FALSE),"") | AS10: =IF(AT10="","",TEXT(AT10,"dd")&"-"&TEXT(AU10,"dd mmm")) | AT10: =IFERROR($M10+VLOOKUP($L10,'Voyage days'!$F$382:$H$446,3,FALSE),"") | AU10: =IFERROR($N10+VLOOKUP($L10,'Voyage days'!$F$382:$H$446,3,FALSE),"") | AV10: =IF(AW10="","",TEXT(AW10,"dd")&"-"&TEXT(AX10,"dd mmm")) | AW10: =IFERROR($M10+VLOOKUP($L10,'Voyage days'!$F$483:$H$538,3,FALSE),"") | AX10: =IFERROR($N10+VLOOKUP($L10,'Voyage days'!$F$483:$H$538,3,FALSE),"") | AY10: =IF(AZ10="","",TEXT(AZ10,"dd")&"-"&TEXT(BA10,"dd mmm")) | AZ10: =IFERROR($M10+VLOOKUP($L10,'Voyage days'!$F$540:$H$613,3,FALSE),"") | BA10: =IFERROR($N10+VLOOKUP($L10,'Voyage days'!$F$540:$H$613,3,FALSE),"") | BB10: =IF(BC10="","",TEXT(BC10,"dd")&"-"&TEXT(BD10,"dd mmm")) | BC10: =IFERROR($M10+VLOOKUP($L10,'Voyage days'!$F$448:$H$479,3,FALSE),"") | BD10: =IFERROR($N10+VLOOKUP($L10,'Voyage days'!$F$448:$H$479,3,FALSE),"") | BE10: =IF(BF10="","",TEXT(BF10,"dd")&"-"&TEXT(BG10,"dd mmm")) | BF10: =IFERROR($M10+VLOOKUP($L10,'Voyage days'!$F$620:$H$646,3,FALSE),"") | BG10: =IFERROR($N10+VLOOKUP($L10,'Voyage days'!$F$620:$H$646,3,FALSE),"") | BH10: =IF(BI10="","",TEXT(BI10,"dd")&"-"&TEXT(BL10,"dd mmm")) | BI10: =IFERROR($M10+VLOOKUP($L10,'Voyage days'!$F$702:$H$727,3,FALSE),"") | BJ10: =IF(BK10="","",TEXT(BK10,"dd")&"-"&TEXT(BL10,"dd mmm")) | BK10: =IFERROR($M10+VLOOKUP($L10,'Voyage days'!$F$807:$H$878,3,FALSE),"") | BL10: =IFERROR($N10+VLOOKUP($L10,'Voyage days'!$F$807:$H$878,3,FALSE),"") | BM10: =IFERROR($N10+VLOOKUP($L10,'Voyage days'!$F$807:$K$878,6,FALSE),"") | BN10: =if(L10="loads AG", IFERROR($M10+VLOOKUP($L10,'Voyage days'!$M$38:$O$38,3,FALSE),""),"") | BO10: =if(L10="loads USG", IFERROR($M10+VLOOKUP($L10,'Voyage days'!$L$203:$N$203,3,FALSE),""),"")
A11: Laurel Prime | B11: 43435 | C11: 83000 | I11: Astomos | J11: =IF(W11="","NO AIS",IF((W11-M11-1)>0,"Update","")) -> Update | L11: loads USG | M11: 46126 | N11: 46127 | P11: @ Houston anchorage 09 Apr, waiting to berth | R11: Exxon 09-10 Apr USG | S11: BR | T11: 46124 | U11: =IF(V11="","No AIS",VLOOKUP(V11,'Voyage days'!$A$3:$B$1480,2,FALSE)) -> Panama | V11: =IF(VLOOKUP(A11,'1) Kpler'!$E$2:$P$1000,8, FALSE)="","",VLOOKUP(A11,'1) Kpler'!$E$2:$P$1000,8, FALSE)) -> Panama Canal | W11: =IF(VLOOKUP(A11,'1) Kpler'!$E$2:$P$1000,9,FALSE)="","",VLOOKUP(A11,'1) Kpler'!$E$2:$P$1000,9,FALSE)) -> 46136.875 | X11: =VLOOKUP(A11,'1) Kpler'!$E$2:$I$1000,4,FALSE) -> loaded | Y11: =AG11 | Z11: =AJ11 -> 14-15 Apr | AA11: =AM11 -> 14-15 Apr | AB11: =AP11 | AC11: =AS11 -> 04-05 May | AD11: =BB11 | AE11: =AY11 | AF11: =BJ11 | AG11: =IF(AH11="","",TEXT(AH11,"dd")&"-"&TEXT(AI11,"dd mmm")) | AH11: =IFERROR($M11+VLOOKUP($L11,'Voyage days'!$F$38:$H$89,3,FALSE),"") | AI11: =IFERROR(N11+VLOOKUP($L11,'Voyage days'!$F$38:$H$89,3,FALSE),"") | AJ11: =IF(AK11="","",TEXT(AK11,"dd")&"-"&TEXT(AL11,"dd mmm")) -> 14-15 Apr | AK11: =IFERROR($M11+VLOOKUP($L11,'Voyage days'!$F$94:$H$193,3,FALSE),"") -> 46126 | AL11: =IFERROR($N11+VLOOKUP($L11,'Voyage days'!$F$94:$H$193,3,FALSE),"") -> 46127 | AM11: =IF(AN11="","",TEXT(AN11,"dd")&"-"&TEXT(AO11,"dd mmm")) -> 14-15 Apr | AN11: =IFERROR($M11+VLOOKUP($L11,'Voyage days'!$F$203:$H$256,3,FALSE),"") -> 46126 | AO11: =IFERROR($N11+VLOOKUP($L11,'Voyage days'!$F$203:$H$256,3,FALSE),"") -> 46127 | AP11: =IF(AQ11="","",TEXT(AQ11,"dd")&"-"&TEXT(AR11,"dd mmm")) | AQ11: =IFERROR($M11+VLOOKUP($L11,'Voyage days'!$F$294:$H$377,3,FALSE),"") | AR11: =IFERROR($N11+VLOOKUP($L11,'Voyage days'!$F$294:$H$377,3,FALSE),"") | AS11: =IF(AT11="","",TEXT(AT11,"dd")&"-"&TEXT(AU11,"dd mmm")) -> 04-05 May | AT11: =IFERROR($M11+VLOOKUP($L11,'Voyage days'!$F$382:$H$446,3,FALSE),"") -> 46146 | AU11: =IFERROR($N11+VLOOKUP($L11,'Voyage days'!$F$382:$H$446,3,FALSE),"") -> 46147 | AV11: =IF(AW11="","",TEXT(AW11,"dd")&"-"&TEXT(AX11,"dd mmm")) | AW11: =IFERROR($M11+VLOOKUP($L11,'Voyage days'!$F$483:$H$538,3,FALSE),"") | AX11: =IFERROR($N11+VLOOKUP($L11,'Voyage days'!$F$483:$H$538,3,FALSE),"") | AY11: =IF(AZ11="","",TEXT(AZ11,"dd")&"-"&TEXT(BA11,"dd mmm")) | AZ11: =IFERROR($M11+VLOOKUP($L11,'Voyage days'!$F$540:$H$613,3,FALSE),"") | BA11: =IFERROR($N11+VLOOKUP($L11,'Voyage days'!$F$540:$H$613,3,FALSE),"") | BB11: =IF(BC11="","",TEXT(BC11,"dd")&"-"&TEXT(BD11,"dd mmm")) | BC11: =IFERROR($M11+VLOOKUP($L11,'Voyage days'!$F$448:$H$479,3,FALSE),"") | BD11: =IFERROR($N11+VLOOKUP($L11,'Voyage days'!$F$448:$H$479,3,FALSE),"") | BE11: =IF(BF11="","",TEXT(BF11,"dd")&"-"&TEXT(BG11,"dd mmm")) | BF11: =IFERROR($M11+VLOOKUP($L11,'Voyage days'!$F$620:$H$646,3,FALSE),"") | BG11: =IFERROR($N11+VLOOKUP($L11,'Voyage days'!$F$620:$H$646,3,FALSE),"") | BH11: =IF(BI11="","",TEXT(BI11,"dd")&"-"&TEXT(BL11,"dd mmm")) | BI11: =IFERROR($M11+VLOOKUP($L11,'Voyage days'!$F$702:$H$727,3,FALSE),"") | BJ11: =IF(BK11="","",TEXT(BK11,"dd")&"-"&TEXT(BL11,"dd mmm")) | BK11: =IFERROR($M11+VLOOKUP($L11,'Voyage days'!$F$807:$H$878,3,FALSE),"") | BL11: =IFERROR($N11+VLOOKUP($L11,'Voyage days'!$F$807:$H$878,3,FALSE),"") | BM11: =IFERROR($N11+VLOOKUP($L11,'Voyage days'!$F$807:$K$878,6,FALSE),"") | BN11: =if(L11="loads AG", IFERROR($M11+VLOOKUP($L11,'Voyage days'!$M$38:$O$38,3,FALSE),""),"") | BO11: =if(L11="loads USG", IFERROR($M11+VLOOKUP($L11,'Voyage days'!$L$203:$N$203,3,FALSE),""),"") -> 46158
A12: Legend Prosperity | B12: 42370 | C12: 83000 | I12: Astomos | J12: =IF(W12="","NO AIS",IF((W12-M12-1)>0,"Update","")) | L12: Japan | M12: 46138 | N12: 46139 | P12: ETA 1st port Sodegaura 20 Apr | R12: Astomos 18-19 Mar Enterprise | S12: BR | T12: 46124 | U12: =IF(V12="","No AIS",VLOOKUP(V12,'Voyage days'!$A$3:$B$1480,2,FALSE)) -> Japan + 6 | V12: =IF(VLOOKUP(A12,'1) Kpler'!$E$2:$P$1000,8, FALSE)="","",VLOOKUP(A12,'1) Kpler'!$E$2:$P$1000,8, FALSE)) -> Chiba | W12: =IF(VLOOKUP(A12,'1) Kpler'!$E$2:$P$1000,9,FALSE)="","",VLOOKUP(A12,'1) Kpler'!$E$2:$P$1000,9,FALSE)) -> 46133.354 | X12: =VLOOKUP(A12,'1) Kpler'!$E$2:$I$1000,4,FALSE) -> loaded | Y12: =AG12 -> 14-15 May | Z12: =AJ12 -> 28-29 May | AA12: =AM12 -> 07-08 Jun | AB12: =AP12 -> 26-27 May | AC12: =AS12 -> 01-02 Jun | AD12: =BB12 -> 04-05 May | AE12: =AY12 -> 04-05 May | AF12: =BJ12 -> 11-12 Jun | AG12: =IF(AH12="","",TEXT(AH12,"dd")&"-"&TEXT(AI12,"dd mmm")) -> 14-15 May | AH12: =IFERROR($M12+VLOOKUP($L12,'Voyage days'!$F$38:$H$89,3,FALSE),"") -> 46156 | AI12: =IFERROR(N12+VLOOKUP($L12,'Voyage days'!$F$38:$H$89,3,FALSE),"") -> 46157 | AJ12: =IF(AK12="","",TEXT(AK12,"dd")&"-"&TEXT(AL12,"dd mmm")) -> 28-29 May | AK12: =IFERROR($M12+VLOOKUP($L12,'Voyage days'!$F$94:$H$193,3,FALSE),"") -> 46170 | AL12: =IFERROR($N12+VLOOKUP($L12,'Voyage days'!$F$94:$H$193,3,FALSE),"") -> 46171 | AM12: =IF(AN12="","",TEXT(AN12,"dd")&"-"&TEXT(AO12,"dd mmm")) -> 07-08 Jun | AN12: =IFERROR($M12+VLOOKUP($L12,'Voyage days'!$F$203:$H$256,3,FALSE),"") -> 46180 | AO12: =IFERROR($N12+VLOOKUP($L12,'Voyage days'!$F$203:$H$256,3,FALSE),"") -> 46181 | AP12: =IF(AQ12="","",TEXT(AQ12,"dd")&"-"&TEXT(AR12,"dd mmm")) -> 26-27 May | AQ12: =IFERROR($M12+VLOOKUP($L12,'Voyage days'!$F$294:$H$377,3,FALSE),"") -> 46168 | AR12: =IFERROR($N12+VLOOKUP($L12,'Voyage days'!$F$294:$H$377,3,FALSE),"") -> 46169 | AS12: =IF(AT12="","",TEXT(AT12,"dd")&"-"&TEXT(AU12,"dd mmm")) -> 01-02 Jun | AT12: =IFERROR($M12+VLOOKUP($L12,'Voyage days'!$F$382:$H$446,3,FALSE),"") -> 46174 | AU12: =IFERROR($N12+VLOOKUP($L12,'Voyage days'!$F$382:$H$446,3,FALSE),"") -> 46175 | AV12: =IF(AW12="","",TEXT(AW12,"dd")&"-"&TEXT(AX12,"dd mmm")) -> 09-10 May | AW12: =IFERROR($M12+VLOOKUP($L12,'Voyage days'!$F$483:$H$538,3,FALSE),"") -> 46151 | AX12: =IFERROR($N12+VLOOKUP($L12,'Voyage days'!$F$483:$H$538,3,FALSE),"") -> 46152 | AY12: =IF(AZ12="","",TEXT(AZ12,"dd")&"-"&TEXT(BA12,"dd mmm")) -> 04-05 May | AZ12: =IFERROR($M12+VLOOKUP($L12,'Voyage days'!$F$540:$H$613,3,FALSE),"") -> 46146.25 | BA12: =IFERROR($N12+VLOOKUP($L12,'Voyage days'!$F$540:$H$613,3,FALSE),"") -> 46147.25 | BB12: =IF(BC12="","",TEXT(BC12,"dd")&"-"&TEXT(BD12,"dd mmm")) -> 04-05 May | BC12: =IFERROR($M12+VLOOKUP($L12,'Voyage days'!$F$448:$H$479,3,FALSE),"") -> 46146 | BD12: =IFERROR($N12+VLOOKUP($L12,'Voyage days'!$F$448:$H$479,3,FALSE),"") -> 46147 | BE12: =IF(BF12="","",TEXT(BF12,"dd")&"-"&TEXT(BG12,"dd mmm")) -> 07-08 May | BF12: =IFERROR($M12+VLOOKUP($L12,'Voyage days'!$F$620:$H$646,3,FALSE),"") -> 46149 | BG12: =IFERROR($N12+VLOOKUP($L12,'Voyage days'!$F$620:$H$646,3,FALSE),"") -> 46150 | BH12: =IF(BI12="","",TEXT(BI12,"dd")&"-"&TEXT(BL12,"dd mmm")) -> 04-12 Jun | BI12: =IFERROR($M12+VLOOKUP($L12,'Voyage days'!$F$702:$H$727,3,FALSE),"") -> 46146.25 | BJ12: =IF(BK12="","",TEXT(BK12,"dd")&"-"&TEXT(BL12,"dd mmm")) -> 11-12 Jun | BK12: =IFERROR($M12+VLOOKUP($L12,'Voyage days'!$F$807:$H$878,3,FALSE),"") -> 46184 | BL12: =IFERROR($N12+VLOOKUP($L12,'Voyage days'!$F$807:$H$878,3,FALSE),"") -> 46185 | BM12: =IFERROR($N12+VLOOKUP($L12,'Voyage days'!$F$807:$K$878,6,FALSE),"") -> 46159 | BN12: =if(L12="loads AG", IFERROR($M12+VLOOKUP($L12,'Voyage days'!$M$38:$O$38,3,FALSE),""),"") | BO12: =if(L12="loads USG", IFERROR($M12+VLOOKUP($L12,'Voyage days'!$L$203:$N$203,3,FALSE),""),"")
A13: Leto Providence | B13: 37981 | C13: 78908 | I13: Astomos | J13: =IF(W13="","NO AIS",IF((W13-M13-1)>0,"Update","")) -> Update | L13: loads USG | M13: 46125 | N13: 46126 | P13: @ Nederland 12 Apr, still loading | R13: Astomos 09-10 Apr Nederland | S13: BR | T13: 46124 | U13: =IF(V13="","No AIS",VLOOKUP(V13,'Voyage days'!$A$3:$B$1480,2,FALSE)) -> Indo + 4 | V13: =IF(VLOOKUP(A13,'1) Kpler'!$E$2:$P$1000,8, FALSE)="","",VLOOKUP(A13,'1) Kpler'!$E$2:$P$1000,8, FALSE)) -> Pupuk Ammonia | W13: =IF(VLOOKUP(A13,'1) Kpler'!$E$2:$P$1000,9,FALSE)="","",VLOOKUP(A13,'1) Kpler'!$E$2:$P$1000,9,FALSE)) -> 46166.125 | X13: =VLOOKUP(A13,'1) Kpler'!$E$2:$I$1000,4,FALSE) -> loaded | Y13: =AG13 | Z13: =AJ13 -> 13-14 Apr | AA13: =AM13 -> 13-14 Apr | AB13: =AP13 | AC13: =AS13 -> 03-04 May | AD13: =BB13 | AE13: =AY13 | AF13: =BJ13 | AG13: =IF(AH13="","",TEXT(AH13,"dd")&"-"&TEXT(AI13,"dd mmm")) | AH13: =IFERROR($M13+VLOOKUP($L13,'Voyage days'!$F$38:$H$89,3,FALSE),"") | AI13: =IFERROR(N13+VLOOKUP($L13,'Voyage days'!$F$38:$H$89,3,FALSE),"") | AJ13: =IF(AK13="","",TEXT(AK13,"dd")&"-"&TEXT(AL13,"dd mmm")) -> 13-14 Apr | AK13: =IFERROR($M13+VLOOKUP($L13,'Voyage days'!$F$94:$H$193,3,FALSE),"") -> 46125 | AL13: =IFERROR($N13+VLOOKUP($L13,'Voyage days'!$F$94:$H$193,3,FALSE),"") -> 46126 | AM13: =IF(AN13="","",TEXT(AN13,"dd")&"-"&TEXT(AO13,"dd mmm")) -> 13-14 Apr | AN13: =IFERROR($M13+VLOOKUP($L13,'Voyage days'!$F$203:$H$256,3,FALSE),"") -> 46125 | AO13: =IFERROR($N13+VLOOKUP($L13,'Voyage days'!$F$203:$H$256,3,FALSE),"") -> 46126 | AP13: =IF(AQ13="","",TEXT(AQ13,"dd")&"-"&TEXT(AR13,"dd mmm")) | AQ13: =IFERROR($M13+VLOOKUP($L13,'Voyage days'!$F$294:$H$377,3,FALSE),"") | AR13: =IFERROR($N13+VLOOKUP($L13,'Voyage days'!$F$294:$H$377,3,FALSE),"") | AS13: =IF(AT13="","",TEXT(AT13,"dd")&"-"&TEXT(AU13,"dd mmm")) -> 03-04 May | AT13: =IFERROR($M13+VLOOKUP($L13,'Voyage days'!$F$382:$H$446,3,FALSE),"") -> 46145 | AU13: =IFERROR($N13+VLOOKUP($L13,'Voyage days'!$F$382:$H$446,3,FALSE),"") -> 46146 | AV13: =IF(AW13="","",TEXT(AW13,"dd")&"-"&TEXT(AX13,"dd mmm")) | AW13: =IFERROR($M13+VLOOKUP($L13,'Voyage days'!$F$483:$H$538,3,FALSE),"") | AX13: =IFERROR($N13+VLOOKUP($L13,'Voyage days'!$F$483:$H$538,3,FALSE),"") | AY13: =IF(AZ13="","",TEXT(AZ13,"dd")&"-"&TEXT(BA13,"dd mmm")) | AZ13: =IFERROR($M13+VLOOKUP($L13,'Voyage days'!$F$540:$H$613,3,FALSE),"") | BA13: =IFERROR($N13+VLOOKUP($L13,'Voyage days'!$F$540:$H$613,3,FALSE),"") | BB13: =IF(BC13="","",TEXT(BC13,"dd")&"-"&TEXT(BD13,"dd mmm")) | BC13: =IFERROR($M13+VLOOKUP($L13,'Voyage days'!$F$448:$H$479,3,FALSE),"") | BD13: =IFERROR($N13+VLOOKUP($L13,'Voyage days'!$F$448:$H$479,3,FALSE),"") | BE13: =IF(BF13="","",TEXT(BF13,"dd")&"-"&TEXT(BG13,"dd mmm")) | BF13: =IFERROR($M13+VLOOKUP($L13,'Voyage days'!$F$620:$H$646,3,FALSE),"") | BG13: =IFERROR($N13+VLOOKUP($L13,'Voyage days'!$F$620:$H$646,3,FALSE),"") | BH13: =IF(BI13="","",TEXT(BI13,"dd")&"-"&TEXT(BL13,"dd mmm")) | BI13: =IFERROR($M13+VLOOKUP($L13,'Voyage days'!$F$702:$H$727,3,FALSE),"") | BJ13: =IF(BK13="","",TEXT(BK13,"dd")&"-"&TEXT(BL13,"dd mmm")) | BK13: =IFERROR($M13+VLOOKUP($L13,'Voyage days'!$F$807:$H$878,3,FALSE),"") | BL13: =IFERROR($N13+VLOOKUP($L13,'Voyage days'!$F$807:$H$878,3,FALSE),"") | BM13: =IFERROR($N13+VLOOKUP($L13,'Voyage days'!$F$807:$K$878,6,FALSE),"") | BN13: =if(L13="loads AG", IFERROR($M13+VLOOKUP($L13,'Voyage days'!$M$38:$O$38,3,FALSE),""),"") | BO13: =if(L13="loads USG", IFERROR($M13+VLOOKUP($L13,'Voyage days'!$L$203:$N$203,3,FALSE),""),"") -> 46157
